2021-11-06 19:30:17 WARNING (SyncWorker_0) [homeassistant.util.yaml.loader] YAML file /config/sensors/statistics_energy.yaml contains duplicate key "platform". Check lines 0 and 4
2021-11-06 19:30:17 WARNING (SyncWorker_0) [homeassistant.util.yaml.loader] YAML file /config/sensors/statistics_energy.yaml contains duplicate key "entity_id". Check lines 1 and 5
2021-11-06 19:30:17 WARNING (SyncWorker_0) [homeassistant.util.yaml.loader] YAML file /config/sensors/statistics_energy.yaml contains duplicate key "name". Check lines 2 and 6
2021-11-06 19:30:17 WARNING (SyncWorker_0) [homeassistant.util.yaml.loader] YAML file /config/sensors/statistics_energy.yaml contains duplicate key "platform". Check lines 4 and 8
2021-11-06 19:30:17 WARNING (SyncWorker_0) [homeassistant.util.yaml.loader] YAML file /config/sensors/statistics_energy.yaml contains duplicate key "entity_id". Check lines 5 and 9
2021-11-06 19:30:17 WARNING (SyncWorker_0) [homeassistant.util.yaml.loader] YAML file /config/sensors/statistics_energy.yaml contains duplicate key "name". Check lines 6 and 10
2021-11-06 19:30:17 WARNING (SyncWorker_0) [homeassistant.util.yaml.loader] YAML file /config/sensors/statistics_energy.yaml contains duplicate key "platform". Check lines 8 and 12
2021-11-06 19:30:17 WARNING (SyncWorker_0) [homeassistant.util.yaml.loader] YAML file /config/sensors/statistics_energy.yaml contains duplicate key "entity_id". Check lines 9 and 13
2021-11-06 19:30:17 WARNING (SyncWorker_0) [homeassistant.util.yaml.loader] YAML file /config/sensors/statistics_energy.yaml contains duplicate key "name". Check lines 10 and 14
2021-11-06 19:30:20 WARNING (SyncWorker_1) [homeassistant.loader] We found a custom integration nodered which has not been tested by Home Assistant. This component might cause stability problems, be sure to disable it if you experience issues with Home Assistant
2021-11-06 19:30:20 WARNING (SyncWorker_0) [homeassistant.loader] We found a custom integration powercalc which has not been tested by Home Assistant. This component might cause stability problems, be sure to disable it if you experience issues with Home Assistant
2021-11-06 19:30:20 WARNING (SyncWorker_2) [homeassistant.loader] We found a custom integration average which has not been tested by Home Assistant. This component might cause stability problems, be sure to disable it if you experience issues with Home Assistant
2021-11-06 19:30:20 WARNING (SyncWorker_0) [homeassistant.loader] We found a custom integration weatherbit which has not been tested by Home Assistant. This component might cause stability problems, be sure to disable it if you experience issues with Home Assistant
2021-11-06 19:30:20 WARNING (SyncWorker_0) [homeassistant.loader] We found a custom integration hpprinter which has not been tested by Home Assistant. This component might cause stability problems, be sure to disable it if you experience issues with Home Assistant
2021-11-06 19:30:20 WARNING (SyncWorker_1) [homeassistant.loader] We found a custom integration alexa_media which has not been tested by Home Assistant. This component might cause stability problems, be sure to disable it if you experience issues with Home Assistant
2021-11-06 19:30:20 WARNING (SyncWorker_2) [homeassistant.loader] We found a custom integration myenergi which has not been tested by Home Assistant. This component might cause stability problems, be sure to disable it if you experience issues with Home Assistant
2021-11-06 19:30:20 WARNING (SyncWorker_0) [homeassistant.loader] We found a custom integration hacs which has not been tested by Home Assistant. This component might cause stability problems, be sure to disable it if you experience issues with Home Assistant
2021-11-06 19:30:20 WARNING (SyncWorker_3) [homeassistant.loader] We found a custom integration lovelace_gen which has not been tested by Home Assistant. This component might cause stability problems, be sure to disable it if you experience issues with Home Assistant
2021-11-06 19:30:20 WARNING (SyncWorker_1) [homeassistant.loader] We found a custom integration alarmo which has not been tested by Home Assistant. This component might cause stability problems, be sure to disable it if you experience issues with Home Assistant
2021-11-06 19:30:20 WARNING (SyncWorker_0) [homeassistant.loader] We found a custom integration garbage_collection which has not been tested by Home Assistant. This component might cause stability problems, be sure to disable it if you experience issues with Home Assistant
2021-11-06 19:30:20 WARNING (SyncWorker_2) [homeassistant.loader] We found a custom integration media_player_template which has not been tested by Home Assistant. This component might cause stability problems, be sure to disable it if you experience issues with Home Assistant
2021-11-06 19:30:20 WARNING (SyncWorker_0) [homeassistant.loader] We found a custom integration auto_backup which has not been tested by Home Assistant. This component might cause stability problems, be sure to disable it if you experience issues with Home Assistant
2021-11-06 19:30:20 WARNING (SyncWorker_4) [homeassistant.loader] We found a custom integration pirateweather which has not been tested by Home Assistant. This component might cause stability problems, be sure to disable it if you experience issues with Home Assistant
2021-11-06 19:30:20 WARNING (SyncWorker_1) [homeassistant.loader] We found a custom integration mail_and_packages which has not been tested by Home Assistant. This component might cause stability problems, be sure to disable it if you experience issues with Home Assistant
2021-11-06 19:30:20 WARNING (SyncWorker_6) [homeassistant.loader] We found a custom integration myq which has not been tested by Home Assistant. This component might cause stability problems, be sure to disable it if you experience issues with Home Assistant
2021-11-06 19:30:40 WARNING (MainThread) [homeassistant.helpers.template] Template variable warning: 'None' has no attribute 'state' when rendering '<ha-icon icon="mdi:home-assistant"></ha-icon>&nbsp;**Add-ons needing update:** &nbsp;&nbsp; {{ states.sensor.supervisor_updates.state }}

> {% for addon in states.sensor.supervisor_updates.attributes.addons %}
> {{ addon.name }}&nbsp; {{ addon.version }} -> {{ addon.version_latest }}
> {% endfor %}

<ha-icon icon="hacs:hacs"></ha-icon>&nbsp;**HACS updates available:** &nbsp;&nbsp; {{ states.sensor.hacs.state }}

> {% for repo in states.sensor.hacs.attributes.repositories %}
>    **{{ repo.display_name }}** _{{ repo["installed_version"] }}_ -> _{{ repo["available_version"] }}_
> {% endfor %}
---
|          | Current&nbsp;&nbsp;&nbsp; |   Latest  |
|--- |:---: |:---:           |
| **Supervisor**&nbsp;&nbsp;&nbsp;    | {{ states.sensor.supervisor_updates.attributes.current_version }} | {{ states.sensor.supervisor_updates.attributes.newest_version }} |
| **Core**          | {{ states.sensor.updater_core.attributes.current_version }} | {{ states.sensor.updater_core.attributes.newest_version }} |
| **Audio**         | {{ states.sensor.updater_audio.attributes.current_version }} | {{ states.sensor.updater_audio.attributes.newest_version }} |
| **CLI**           | {{ states.sensor.updater_cli.attributes.current_version }} | {{ states.sensor.updater_cli.attributes.newest_version }} |
| **DNS**           | {{ states.sensor.updater_dns.attributes.current_version }} |  {{ states.sensor.updater_dns.attributes.newest_version }} |
| **OS**            | {{ states.sensor.os_updates.attributes.installed_version }} | {{ states.sensor.os_updates.attributes.latest_version }} |
| **Multicast**     | {{ states.sensor.updater_multicast.attributes.current_version }} |  {{ states.sensor.updater_multicast.attributes.newest_version }} |'
2021-11-06 19:30:40 ERROR (MainThread) [homeassistant.helpers.template] Template variable error: 'None' has no attribute 'attributes' when rendering '<ha-icon icon="mdi:home-assistant"></ha-icon>&nbsp;**Add-ons needing update:** &nbsp;&nbsp; {{ states.sensor.supervisor_updates.state }}

> {% for addon in states.sensor.supervisor_updates.attributes.addons %}
> {{ addon.name }}&nbsp; {{ addon.version }} -> {{ addon.version_latest }}
> {% endfor %}

<ha-icon icon="hacs:hacs"></ha-icon>&nbsp;**HACS updates available:** &nbsp;&nbsp; {{ states.sensor.hacs.state }}

> {% for repo in states.sensor.hacs.attributes.repositories %}
>    **{{ repo.display_name }}** _{{ repo["installed_version"] }}_ -> _{{ repo["available_version"] }}_
> {% endfor %}
---
|          | Current&nbsp;&nbsp;&nbsp; |   Latest  |
|--- |:---: |:---:           |
| **Supervisor**&nbsp;&nbsp;&nbsp;    | {{ states.sensor.supervisor_updates.attributes.current_version }} | {{ states.sensor.supervisor_updates.attributes.newest_version }} |
| **Core**          | {{ states.sensor.updater_core.attributes.current_version }} | {{ states.sensor.updater_core.attributes.newest_version }} |
| **Audio**         | {{ states.sensor.updater_audio.attributes.current_version }} | {{ states.sensor.updater_audio.attributes.newest_version }} |
| **CLI**           | {{ states.sensor.updater_cli.attributes.current_version }} | {{ states.sensor.updater_cli.attributes.newest_version }} |
| **DNS**           | {{ states.sensor.updater_dns.attributes.current_version }} |  {{ states.sensor.updater_dns.attributes.newest_version }} |
| **OS**            | {{ states.sensor.os_updates.attributes.installed_version }} | {{ states.sensor.os_updates.attributes.latest_version }} |
| **Multicast**     | {{ states.sensor.updater_multicast.attributes.current_version }} |  {{ states.sensor.updater_multicast.attributes.newest_version }} |'
2021-11-06 19:30:46 ERROR (SyncWorker_6) [homeassistant.components.influxdb] Cannot connect to InfluxDB due to 'HTTPConnectionPool(host='a0d7b954-influxdb', port=8086): Max retries exceeded with url: /write?db=homeassistant (Caused by NewConnectionError('<urllib3.connection.HTTPConnection object at 0x7fcec7292c10>: Failed to establish a new connection: [Errno 111] Connection refused'))'. Please check that the provided connection details (host, port, etc.) are correct and that your InfluxDB server is running and accessible. Retrying in 60 seconds.
2021-11-06 19:30:56 WARNING (MainThread) [homeassistant.setup] Setup of input_boolean is taking over 10 seconds.
2021-11-06 19:30:56 WARNING (MainThread) [homeassistant.setup] Setup of group is taking over 10 seconds.
2021-11-06 19:30:56 WARNING (MainThread) [homeassistant.setup] Setup of zone is taking over 10 seconds.
2021-11-06 19:31:01 WARNING (MainThread) [homeassistant.components.weather] Setup of weather platform pirateweather is taking over 10 seconds.
2021-11-06 19:31:01 WARNING (MainThread) [homeassistant.components.alarm_control_panel] Setup of alarm_control_panel platform manual is taking over 10 seconds.
2021-11-06 19:31:08 WARNING (MainThread) [homeassistant.config_entries] Config entry 'benchdog93@gmail.com' for uptimerobot integration not ready yet: Request timeout for 'https://api.uptimerobot.com/v2/getMonitors'; Retrying in background
2021-11-06 19:31:08 WARNING (MainThread) [homeassistant.config_entries] Config entry 'Home' for accuweather integration not ready yet; Retrying in background
2021-11-06 19:31:08 WARNING (SyncWorker_3) [homeassistant.components.local_file.camera] Could not read camera mail_usps image from file: /custom_components/mail_and_packages/mail_none.gif
2021-11-06 19:31:09 WARNING (MainThread) [homeassistant.setup] Setup of webostv is taking over 10 seconds.
2021-11-06 19:31:09 WARNING (MainThread) [homeassistant.components.weather] Setup of weather platform openweathermap is taking over 10 seconds.
2021-11-06 19:31:12 WARNING (MainThread) [alexapy.alexalogin] No access token found; falling back to credential login instead of oauth.
2021-11-06 19:31:15 WARNING (MainThread) [homeassistant.components.webhook] Received message for unregistered webhook 34cf86c0b787150663ccd67f1f4949b1e2c916a1eaeb0bb6c3fe85a823a891f6 from 192.168.1.1
2021-11-06 19:31:27 WARNING (MainThread) [homeassistant.components.media_player] Setup of media_player platform dlna_dmr is taking over 10 seconds.
2021-11-06 19:31:28 WARNING (MainThread) [aioesphomeapi.reconnect_logic] Can't connect to ESPHome API for washing-machine.local @ washing-machine.local: Error resolving IP address: [Errno -2] Name does not resolve
2021-11-06 19:31:28 WARNING (MainThread) [aioesphomeapi.reconnect_logic] Can't connect to ESPHome API for kitchen-circuit-0.local @ kitchen-circuit-0.local: Error resolving IP address: [Errno -2] Name does not resolve
2021-11-06 19:31:28 WARNING (MainThread) [aioesphomeapi.reconnect_logic] Can't connect to ESPHome API for dish-washer.local @ dish-washer.local: Error resolving IP address: [Errno -2] Name does not resolve
2021-11-06 19:31:28 WARNING (MainThread) [aioesphomeapi.reconnect_logic] Can't connect to ESPHome API for cloths-dryer.local @ cloths-dryer.local: Error resolving IP address: [Errno -2] Name does not resolve
2021-11-06 19:31:29 WARNING (SyncWorker_6) [homeassistant.components.local_file.camera] Could not read camera mail_usps image from file: /custom_components/mail_and_packages/mail_none.gif
2021-11-06 19:31:30 WARNING (MainThread) [homeassistant.components.sensor] Setup of sensor platform pirateweather is taking over 10 seconds.
2021-11-06 19:31:31 WARNING (MainThread) [homeassistant.components.sensor] Setup of sensor platform command_line is taking over 10 seconds.
2021-11-06 19:31:31 WARNING (MainThread) [aioesphomeapi.reconnect_logic] Can't connect to ESPHome API for 192.168.1.115 @ 192.168.1.115: Error connecting to ('192.168.1.115', 6053): [Errno 113] Connect call failed ('192.168.1.115', 6053)
2021-11-06 19:31:33 ERROR (MainThread) [zigpy.application] Couldn't start application
2021-11-06 19:31:33 ERROR (MainThread) [homeassistant.components.zha.core.gateway] Couldn't start deCONZ = dresden elektronik deCONZ protocol: ConBee I/II, RaspBee I/II coordinator
Traceback (most recent call last):
  File "/usr/local/lib/python3.9/site-packages/serial/serialposix.py", line 322, in open
    self.fd = os.open(self.portstr, os.O_RDWR | os.O_NOCTTY | os.O_NONBLOCK)
FileNotFoundError: [Errno 2] No such file or directory: '/dev/serial/by-id/usb-dresden_elektronik_ingenieurtechnik_GmbH_ConBee_II_DE2457145-if00'

During handling of the above exception, another exception occurred:

Traceback (most recent call last):
  File "/usr/src/homeassistant/homeassistant/components/zha/core/gateway.py", line 152, in async_initialize
    self.application_controller = await app_controller_cls.new(
  File "/usr/local/lib/python3.9/site-packages/zigpy/application.py", line 69, in new
    await app.startup(auto_form)
  File "/usr/local/lib/python3.9/site-packages/zigpy_deconz/zigbee/application.py", line 66, in startup
    await self._api.connect()
  File "/usr/local/lib/python3.9/site-packages/zigpy_deconz/api.py", line 245, in connect
    self._uart = await zigpy_deconz.uart.connect(self._config, self)
  File "/usr/local/lib/python3.9/site-packages/zigpy_deconz/uart.py", line 142, in connect
    _, protocol = await serial_asyncio.create_serial_connection(
  File "/usr/local/lib/python3.9/site-packages/serial_asyncio/__init__.py", line 445, in create_serial_connection
    serial_instance = serial.serial_for_url(*args, **kwargs)
  File "/usr/local/lib/python3.9/site-packages/serial/__init__.py", line 90, in serial_for_url
    instance.open()
  File "/usr/local/lib/python3.9/site-packages/serial/serialposix.py", line 325, in open
    raise SerialException(msg.errno, "could not open port {}: {}".format(self._port, msg))
serial.serialutil.SerialException: [Errno 2] could not open port /dev/serial/by-id/usb-dresden_elektronik_ingenieurtechnik_GmbH_ConBee_II_DE2457145-if00: [Errno 2] No such file or directory: '/dev/serial/by-id/usb-dresden_elektronik_ingenieurtechnik_GmbH_ConBee_II_DE2457145-if00'
2021-11-06 19:31:33 WARNING (MainThread) [homeassistant.config_entries] Config entry 'ConBee II - /dev/serial/by-id/usb-dresden_elektronik_ingenieurtechnik_GmbH_ConBee_II_DE2457145-if00, s/n: DE2457145 - dresden elektronik ingenieurtechnik GmbH - 1CF1:0030' for zha integration not ready yet: [Errno 2] could not open port /dev/serial/by-id/usb-dresden_elektronik_ingenieurtechnik_GmbH_ConBee_II_DE2457145-if00: [Errno 2] No such file or directory: '/dev/serial/by-id/usb-dresden_elektronik_ingenieurtechnik_GmbH_ConBee_II_DE2457145-if00'; Retrying in background
2021-11-06 19:31:35 WARNING (MainThread) [homeassistant.helpers.template] Template warning: 'float' got invalid input 'unknown' when rendering template '{{ (states('sensor.benchdog93_home_assistant_config_last_build_duration') | float / 60) | round(2) }}' but no default was specified. Currently 'float' will return '0', however this template will fail to render in Home Assistant core 2022.1
2021-11-06 19:31:35 WARNING (MainThread) [homeassistant.helpers.template] Template warning: 'float' got invalid input 'unknown' when rendering template '{{ (states('sensor.benchdog93_home_assistant_config_last_build_duration') | float / 60) | round(2) }}' but no default was specified. Currently 'float' will return '0', however this template will fail to render in Home Assistant core 2022.1
2021-11-06 19:31:36 ERROR (MainThread) [homeassistant.config_entries] Error unloading entry 192.168.1.24 for binary_sensor
Traceback (most recent call last):
  File "/usr/src/homeassistant/homeassistant/config_entries.py", line 443, in async_unload
    result = await component.async_unload_entry(hass, self)  # type: ignore
  File "/usr/src/homeassistant/homeassistant/components/binary_sensor/__init__.py", line 162, in async_unload_entry
    return await component.async_unload_entry(entry)
  File "/usr/src/homeassistant/homeassistant/helpers/entity_component.py", line 181, in async_unload_entry
    raise ValueError("Config entry was never loaded!")
ValueError: Config entry was never loaded!
2021-11-06 19:31:36 ERROR (MainThread) [homeassistant.config_entries] Error unloading entry 192.168.1.24 for camera
Traceback (most recent call last):
  File "/usr/src/homeassistant/homeassistant/config_entries.py", line 443, in async_unload
    result = await component.async_unload_entry(hass, self)  # type: ignore
  File "/usr/src/homeassistant/homeassistant/components/camera/__init__.py", line 368, in async_unload_entry
    return await component.async_unload_entry(entry)
  File "/usr/src/homeassistant/homeassistant/helpers/entity_component.py", line 181, in async_unload_entry
    raise ValueError("Config entry was never loaded!")
ValueError: Config entry was never loaded!
2021-11-06 19:31:36 ERROR (MainThread) [homeassistant.config_entries] Error unloading entry 192.168.1.24 for sensor
Traceback (most recent call last):
  File "/usr/src/homeassistant/homeassistant/config_entries.py", line 443, in async_unload
    result = await component.async_unload_entry(hass, self)  # type: ignore
  File "/usr/src/homeassistant/homeassistant/components/sensor/__init__.py", line 134, in async_unload_entry
    return await component.async_unload_entry(entry)
  File "/usr/src/homeassistant/homeassistant/helpers/entity_component.py", line 181, in async_unload_entry
    raise ValueError("Config entry was never loaded!")
ValueError: Config entry was never loaded!
2021-11-06 19:31:36 ERROR (MainThread) [homeassistant.config_entries] Error unloading entry 192.168.1.24 for switch
Traceback (most recent call last):
  File "/usr/src/homeassistant/homeassistant/config_entries.py", line 443, in async_unload
    result = await component.async_unload_entry(hass, self)  # type: ignore
  File "/usr/src/homeassistant/homeassistant/components/switch/__init__.py", line 85, in async_unload_entry
    return await component.async_unload_entry(entry)
  File "/usr/src/homeassistant/homeassistant/helpers/entity_component.py", line 181, in async_unload_entry
    raise ValueError("Config entry was never loaded!")
ValueError: Config entry was never loaded!
2021-11-06 19:31:39 WARNING (Recorder) [homeassistant.components.sensor.recorder] sensor.desktop_daily_energy has unknown unit W
2021-11-06 19:31:39 WARNING (Recorder) [homeassistant.components.sensor.recorder] sensor.ewva_daily_energy has unknown unit W
2021-11-06 19:31:39 WARNING (Recorder) [homeassistant.components.sensor.recorder] sensor.master_bath_light_daily_energy has unknown unit W
2021-11-06 19:31:39 WARNING (Recorder) [homeassistant.components.sensor.recorder] sensor.master_bath_fan_daily_energy has unknown unit W
2021-11-06 19:31:39 WARNING (Recorder) [homeassistant.components.sensor.recorder] sensor.pond_aerator_daily_energy has unknown unit kW
2021-11-06 19:31:39 WARNING (Recorder) [homeassistant.components.sensor.recorder] sensor.counter_lights_daily_energy has unknown unit kW
2021-11-06 19:31:39 WARNING (Recorder) [homeassistant.components.sensor.recorder] sensor.tooster_daily_energy has unknown unit kW
2021-11-06 19:31:39 WARNING (Recorder) [homeassistant.components.sensor.recorder] sensor.sink_light_daily_energy has unknown unit W
2021-11-06 19:31:39 WARNING (Recorder) [homeassistant.components.sensor.recorder] sensor.cabinet_lights_daily_energy has unknown unit W
2021-11-06 19:32:06 WARNING (MainThread) [homeassistant.components.media_player] Updating alexa_media media_player took longer than the scheduled update interval 0:00:10
2021-11-06 19:32:07 WARNING (MainThread) [homeassistant.components.binary_sensor] Setup of binary_sensor platform synology_dsm is taking over 10 seconds.
2021-11-06 19:32:07 WARNING (MainThread) [homeassistant.components.camera] Setup of camera platform synology_dsm is taking over 10 seconds.
2021-11-06 19:32:07 WARNING (MainThread) [homeassistant.components.sensor] Setup of sensor platform synology_dsm is taking over 10 seconds.
2021-11-06 19:32:07 WARNING (MainThread) [homeassistant.components.switch] Setup of switch platform synology_dsm is taking over 10 seconds.
2021-11-06 19:32:08 WARNING (MainThread) [homeassistant.helpers.entity] Update of media_player.colleen_s_echo_dot is taking over 10 seconds
2021-11-06 19:32:08 WARNING (MainThread) [homeassistant.helpers.entity] Update of media_player.everywhere is taking over 10 seconds
2021-11-06 19:32:08 WARNING (MainThread) [homeassistant.helpers.entity] Update of media_player.ed_s_echo_dot is taking over 10 seconds
2021-11-06 19:32:08 WARNING (MainThread) [homeassistant.helpers.entity] Update of media_player.livingroom_echo_dot is taking over 10 seconds
2021-11-06 19:32:08 WARNING (MainThread) [homeassistant.components.media_player] Updating webostv media_player took longer than the scheduled update interval 0:00:10
2021-11-06 19:32:08 WARNING (MainThread) [homeassistant.components.media_player] Updating dlna_dmr media_player took longer than the scheduled update interval 0:00:10
2021-11-06 19:32:08 WARNING (MainThread) [homeassistant.helpers.entity] Update of media_player.mancave_tv is taking over 10 seconds
2021-11-06 19:32:08 WARNING (MainThread) [homeassistant.helpers.entity] Update of media_player.lgpc_ed_eds_desktop is taking over 10 seconds
2021-11-06 19:32:15 WARNING (MainThread) [homeassistant.components.media_player] Updating alexa_media media_player took longer than the scheduled update interval 0:00:10
2021-11-06 19:47:48 ERROR (MainThread) [aiohttp.server] Error handling request
Traceback (most recent call last):
  File "/usr/local/lib/python3.9/site-packages/aiohttp/web_protocol.py", line 314, in data_received
    messages, upgraded, tail = self._request_parser.feed_data(data)
  File "aiohttp/_http_parser.pyx", line 546, in aiohttp._http_parser.HttpParser.feed_data
aiohttp.http_exceptions.BadStatusLine: 400, message="Bad status line 'invalid HTTP method'"
2021-11-06 21:01:32 WARNING (MainThread) [aioesphomeapi.reconnect_logic] Can't connect to ESPHome API for cloths-dryer.local @ cloths-dryer.local: Timeout while connecting to ('192.168.1.161', 6053)
2021-11-06 21:04:56 WARNING (MainThread) [aioesphomeapi.reconnect_logic] Can't connect to ESPHome API for washing-machine.local @ washing-machine.local: Timeout while connecting to ('192.168.1.186', 6053)
2021-11-06 21:08:15 WARNING (MainThread) [aioesphomeapi.reconnect_logic] Can't connect to ESPHome API for dish-washer.local @ dish-washer.local: Timeout while connecting to ('192.168.1.103', 6053)
2021-11-06 21:20:00 ERROR (MainThread) [custom_components.auto_backup] Error during backup. Timeout on /backups/new/partial request. There may be a backup already in progress.
2021-11-06 22:02:12 WARNING (MainThread) [aioesphomeapi.reconnect_logic] Can't connect to ESPHome API for spare-plug.local @ spare-plug.local: Timeout while connecting to ('192.168.1.125', 6053)
2021-11-06 22:02:54 ERROR (MainThread) [homeassistant.components.uptimerobot] Error fetching uptimerobot data: Request timeout for 'https://api.uptimerobot.com/v2/getMonitors'
2021-11-06 22:23:41 ERROR (MainThread) [homeassistant.components.hassio.handler] Timeout on /addons/a0d7b954_phpmyadmin/stats request
2021-11-06 22:23:42 ERROR (MainThread) [homeassistant.components.hassio.handler] Timeout on /addons/a0d7b954_esphome/stats request
2021-11-06 22:23:43 ERROR (MainThread) [homeassistant.components.hassio.handler] Timeout on /addons/a0d7b954_zwavejs2mqtt/stats request
2021-11-06 22:23:43 ERROR (MainThread) [homeassistant.components.hassio.handler] Timeout on /addons/core_mariadb/stats request
2021-11-06 22:23:43 ERROR (MainThread) [homeassistant.components.hassio.handler] Timeout on /addons/a0d7b954_portainer/stats request
2021-11-06 22:23:49 WARNING (MainThread) [homeassistant.components.hassio] Can't read Supervisor data: 
2021-11-06 22:23:51 WARNING (MainThread) [homeassistant.components.media_player] Updating webostv media_player took longer than the scheduled update interval 0:00:10
2021-11-06 22:23:51 WARNING (MainThread) [homeassistant.helpers.entity] Update of media_player.mancave_tv is taking over 10 seconds
2021-11-06 22:23:55 WARNING (MainThread) [zigpy_deconz.api] Duplicate or delayed response for 0x:99 sequence
2021-11-06 22:23:56 WARNING (MainThread) [zigpy_deconz.api] No response to 'Command.aps_data_indication' command with seq id '0x99'
2021-11-06 22:24:18 ERROR (MainThread) [homeassistant.components.hassio.handler] Client error on /homeassistant/restart request Server disconnected
