2022-01-11 17:56:13 WARNING (SyncWorker_0) [homeassistant.loader] We found a custom integration average which has not been tested by Home Assistant. This component might cause stability problems, be sure to disable it if you experience issues with Home Assistant
2022-01-11 17:56:13 WARNING (SyncWorker_1) [homeassistant.loader] We found a custom integration powercalc which has not been tested by Home Assistant. This component might cause stability problems, be sure to disable it if you experience issues with Home Assistant
2022-01-11 17:56:13 WARNING (SyncWorker_2) [homeassistant.loader] We found a custom integration lovelace_gen which has not been tested by Home Assistant. This component might cause stability problems, be sure to disable it if you experience issues with Home Assistant
2022-01-11 17:56:13 WARNING (SyncWorker_3) [homeassistant.loader] We found a custom integration myenergi which has not been tested by Home Assistant. This component might cause stability problems, be sure to disable it if you experience issues with Home Assistant
2022-01-11 17:56:13 WARNING (SyncWorker_0) [homeassistant.loader] We found a custom integration hacs which has not been tested by Home Assistant. This component might cause stability problems, be sure to disable it if you experience issues with Home Assistant
2022-01-11 17:56:13 WARNING (SyncWorker_1) [homeassistant.loader] We found a custom integration myq which has not been tested by Home Assistant. This component might cause stability problems, be sure to disable it if you experience issues with Home Assistant
2022-01-11 17:56:13 WARNING (SyncWorker_2) [homeassistant.loader] We found a custom integration alarmo which has not been tested by Home Assistant. This component might cause stability problems, be sure to disable it if you experience issues with Home Assistant
2022-01-11 17:56:13 WARNING (SyncWorker_3) [homeassistant.loader] We found a custom integration media_player_template which has not been tested by Home Assistant. This component might cause stability problems, be sure to disable it if you experience issues with Home Assistant
2022-01-11 17:56:13 WARNING (SyncWorker_0) [homeassistant.loader] We found a custom integration mail_and_packages which has not been tested by Home Assistant. This component might cause stability problems, be sure to disable it if you experience issues with Home Assistant
2022-01-11 17:56:13 WARNING (SyncWorker_2) [homeassistant.loader] We found a custom integration garbage_collection which has not been tested by Home Assistant. This component might cause stability problems, be sure to disable it if you experience issues with Home Assistant
2022-01-11 17:56:13 WARNING (SyncWorker_0) [homeassistant.loader] We found a custom integration auto_backup which has not been tested by Home Assistant. This component might cause stability problems, be sure to disable it if you experience issues with Home Assistant
2022-01-11 17:56:13 WARNING (SyncWorker_4) [homeassistant.loader] We found a custom integration alexa_media which has not been tested by Home Assistant. This component might cause stability problems, be sure to disable it if you experience issues with Home Assistant
2022-01-11 17:56:13 WARNING (SyncWorker_5) [homeassistant.loader] We found a custom integration hpprinter which has not been tested by Home Assistant. This component might cause stability problems, be sure to disable it if you experience issues with Home Assistant
2022-01-11 17:56:13 WARNING (SyncWorker_2) [homeassistant.loader] We found a custom integration pirateweather which has not been tested by Home Assistant. This component might cause stability problems, be sure to disable it if you experience issues with Home Assistant
2022-01-11 17:56:23 WARNING (MainThread) [homeassistant.helpers.template] Template variable warning: 'None' has no attribute 'state' when rendering '<ha-icon icon="mdi:home-assistant"></ha-icon>&nbsp;**Add-on update:** &nbsp;&nbsp; {{ states.sensor.supervisor_updates.state }}

> {% for addon in states.sensor.supervisor_updates.attributes.addons %}
> {{ addon.name }}&nbsp; {{ addon.version }} -> {{ addon.version_latest }}
> {% endfor %}

<ha-icon icon="hacs:hacs"></ha-icon>&nbsp;**HACS updates:** &nbsp;&nbsp; {{ states.sensor.hacs.state }}

> {% for repo in states.sensor.hacs.attributes.repositories %}
>  **{{ repo.display_name }}** _{{ repo["installed_version"] }}_ -> _{{repo["available_version"] }}_
> {% endfor %}'
2022-01-11 17:56:23 ERROR (MainThread) [homeassistant.helpers.template] Template variable error: 'None' has no attribute 'attributes' when rendering '<ha-icon icon="mdi:home-assistant"></ha-icon>&nbsp;**Add-on update:** &nbsp;&nbsp; {{ states.sensor.supervisor_updates.state }}

> {% for addon in states.sensor.supervisor_updates.attributes.addons %}
> {{ addon.name }}&nbsp; {{ addon.version }} -> {{ addon.version_latest }}
> {% endfor %}

<ha-icon icon="hacs:hacs"></ha-icon>&nbsp;**HACS updates:** &nbsp;&nbsp; {{ states.sensor.hacs.state }}

> {% for repo in states.sensor.hacs.attributes.repositories %}
>  **{{ repo.display_name }}** _{{ repo["installed_version"] }}_ -> _{{repo["available_version"] }}_
> {% endfor %}'
2022-01-11 17:56:29 ERROR (MainThread) [homeassistant.setup] Setup failed for nodered: Integration not found.
2022-01-11 17:56:35 WARNING (SyncWorker_5) [homeassistant.components.local_file.camera] Could not read camera mail_usps image from file: /custom_components/mail_and_packages/mail_none.gif
2022-01-11 17:56:36 WARNING (MainThread) [alexapy.alexalogin] No access token found; falling back to credential login instead of oauth.
2022-01-11 17:56:41 WARNING (MainThread) [homeassistant.setup] Setup of zone is taking over 10 seconds.
2022-01-11 17:56:41 WARNING (MainThread) [homeassistant.setup] Setup of webostv is taking over 10 seconds.
2022-01-11 17:56:41 WARNING (MainThread) [homeassistant.config_entries] Config entry 'Home' for accuweather integration not ready yet; Retrying in background
2022-01-11 17:56:43 WARNING (MainThread) [homeassistant.helpers.entity] Entity camera.mail_usps_camera (<class 'custom_components.mail_and_packages.camera.MailCam'>) implements device_state_attributes. Please report it to the custom component author.
2022-01-11 17:56:43 WARNING (MainThread) [homeassistant.helpers.entity] Entity camera.mail_amazon_delivery_camera (<class 'custom_components.mail_and_packages.camera.MailCam'>) implements device_state_attributes. Please report it to the custom component author.
2022-01-11 17:56:45 WARNING (MainThread) [homeassistant.helpers.entity] Entity sensor.mail_amazon_packages_delivered (<class 'custom_components.mail_and_packages.sensor.PackagesSensor'>) implements device_state_attributes. Please report it to the custom component author.
2022-01-11 17:56:45 WARNING (MainThread) [homeassistant.helpers.entity] Entity sensor.mail_amazon_exception (<class 'custom_components.mail_and_packages.sensor.PackagesSensor'>) implements device_state_attributes. Please report it to the custom component author.
2022-01-11 17:56:45 WARNING (MainThread) [homeassistant.helpers.entity] Entity sensor.mail_amazon_packages (<class 'custom_components.mail_and_packages.sensor.PackagesSensor'>) implements device_state_attributes. Please report it to the custom component author.
2022-01-11 17:56:45 WARNING (MainThread) [homeassistant.helpers.entity] Entity sensor.mail_dhl_delivered (<class 'custom_components.mail_and_packages.sensor.PackagesSensor'>) implements device_state_attributes. Please report it to the custom component author.
2022-01-11 17:56:45 WARNING (MainThread) [homeassistant.helpers.entity] Entity sensor.mail_dhl_delivering (<class 'custom_components.mail_and_packages.sensor.PackagesSensor'>) implements device_state_attributes. Please report it to the custom component author.
2022-01-11 17:56:45 WARNING (MainThread) [homeassistant.helpers.entity] Entity sensor.mail_dhl_packages (<class 'custom_components.mail_and_packages.sensor.PackagesSensor'>) implements device_state_attributes. Please report it to the custom component author.
2022-01-11 17:56:45 WARNING (MainThread) [homeassistant.helpers.entity] Entity sensor.mail_fedex_delivered (<class 'custom_components.mail_and_packages.sensor.PackagesSensor'>) implements device_state_attributes. Please report it to the custom component author.
2022-01-11 17:56:45 WARNING (MainThread) [homeassistant.helpers.entity] Entity sensor.mail_fedex_delivering (<class 'custom_components.mail_and_packages.sensor.PackagesSensor'>) implements device_state_attributes. Please report it to the custom component author.
2022-01-11 17:56:45 WARNING (MainThread) [homeassistant.helpers.entity] Entity sensor.mail_fedex_packages (<class 'custom_components.mail_and_packages.sensor.PackagesSensor'>) implements device_state_attributes. Please report it to the custom component author.
2022-01-11 17:56:45 WARNING (MainThread) [homeassistant.helpers.entity] Entity sensor.mail_updated (<class 'custom_components.mail_and_packages.sensor.PackagesSensor'>) implements device_state_attributes. Please report it to the custom component author.
2022-01-11 17:56:45 WARNING (MainThread) [homeassistant.helpers.entity] Entity sensor.mail_ups_delivered (<class 'custom_components.mail_and_packages.sensor.PackagesSensor'>) implements device_state_attributes. Please report it to the custom component author.
2022-01-11 17:56:45 WARNING (MainThread) [homeassistant.helpers.entity] Entity sensor.mail_ups_delivering (<class 'custom_components.mail_and_packages.sensor.PackagesSensor'>) implements device_state_attributes. Please report it to the custom component author.
2022-01-11 17:56:45 WARNING (MainThread) [homeassistant.helpers.entity] Entity sensor.mail_ups_exception (<class 'custom_components.mail_and_packages.sensor.PackagesSensor'>) implements device_state_attributes. Please report it to the custom component author.
2022-01-11 17:56:45 WARNING (MainThread) [homeassistant.helpers.entity] Entity sensor.mail_ups_packages (<class 'custom_components.mail_and_packages.sensor.PackagesSensor'>) implements device_state_attributes. Please report it to the custom component author.
2022-01-11 17:56:45 WARNING (MainThread) [homeassistant.helpers.entity] Entity sensor.mail_usps_delivered (<class 'custom_components.mail_and_packages.sensor.PackagesSensor'>) implements device_state_attributes. Please report it to the custom component author.
2022-01-11 17:56:45 WARNING (MainThread) [homeassistant.helpers.entity] Entity sensor.mail_usps_delivering (<class 'custom_components.mail_and_packages.sensor.PackagesSensor'>) implements device_state_attributes. Please report it to the custom component author.
2022-01-11 17:56:45 WARNING (MainThread) [homeassistant.helpers.entity] Entity sensor.mail_usps_exception (<class 'custom_components.mail_and_packages.sensor.PackagesSensor'>) implements device_state_attributes. Please report it to the custom component author.
2022-01-11 17:56:45 WARNING (MainThread) [homeassistant.helpers.entity] Entity sensor.mail_usps_mail (<class 'custom_components.mail_and_packages.sensor.PackagesSensor'>) implements device_state_attributes. Please report it to the custom component author.
2022-01-11 17:56:45 WARNING (MainThread) [homeassistant.helpers.entity] Entity sensor.mail_usps_packages (<class 'custom_components.mail_and_packages.sensor.PackagesSensor'>) implements device_state_attributes. Please report it to the custom component author.
2022-01-11 17:56:45 WARNING (MainThread) [homeassistant.helpers.entity] Entity sensor.mail_packages_delivered (<class 'custom_components.mail_and_packages.sensor.PackagesSensor'>) implements device_state_attributes. Please report it to the custom component author.
2022-01-11 17:56:45 WARNING (MainThread) [homeassistant.helpers.entity] Entity sensor.mail_packages_in_transit (<class 'custom_components.mail_and_packages.sensor.PackagesSensor'>) implements device_state_attributes. Please report it to the custom component author.
2022-01-11 17:56:45 WARNING (MainThread) [homeassistant.helpers.entity] Entity sensor.mail_image_system_path (<class 'custom_components.mail_and_packages.sensor.ImagePathSensors'>) implements device_state_attributes. Please report it to the custom component author.
2022-01-11 17:56:45 WARNING (MainThread) [homeassistant.helpers.entity] Entity sensor.mail_image_url (<class 'custom_components.mail_and_packages.sensor.ImagePathSensors'>) implements device_state_attributes. Please report it to the custom component author.
2022-01-11 17:56:46 WARNING (MainThread) [homeassistant.setup] Setup of automation is taking over 10 seconds.
2022-01-11 17:56:48 WARNING (MainThread) [alexapy.alexawebsocket] mac_dms not detected; websocket likely won't connect
2022-01-11 17:56:51 WARNING (MainThread) [aioesphomeapi.reconnect_logic] Can't connect to ESPHome API for 192.168.1.115 @ 192.168.1.115: Error connecting to ('192.168.1.115', 6053): [Errno 113] Connect call failed ('192.168.1.115', 6053)
2022-01-11 17:57:18 ERROR (MainThread) [homeassistant.config_entries] Error unloading entry 192.168.1.24 for binary_sensor
Traceback (most recent call last):
  File "/usr/src/homeassistant/homeassistant/config_entries.py", line 452, in async_unload
    result = await component.async_unload_entry(hass, self)  # type: ignore
  File "/usr/src/homeassistant/homeassistant/components/binary_sensor/__init__.py", line 169, in async_unload_entry
    return await component.async_unload_entry(entry)
  File "/usr/src/homeassistant/homeassistant/helpers/entity_component.py", line 177, in async_unload_entry
    raise ValueError("Config entry was never loaded!")
ValueError: Config entry was never loaded!
2022-01-11 17:57:18 ERROR (MainThread) [homeassistant.config_entries] Error unloading entry 192.168.1.24 for camera
Traceback (most recent call last):
  File "/usr/src/homeassistant/homeassistant/config_entries.py", line 452, in async_unload
    result = await component.async_unload_entry(hass, self)  # type: ignore
  File "/usr/src/homeassistant/homeassistant/components/camera/__init__.py", line 366, in async_unload_entry
    return await component.async_unload_entry(entry)
  File "/usr/src/homeassistant/homeassistant/helpers/entity_component.py", line 177, in async_unload_entry
    raise ValueError("Config entry was never loaded!")
ValueError: Config entry was never loaded!
2022-01-11 17:57:18 ERROR (MainThread) [homeassistant.config_entries] Error unloading entry 192.168.1.24 for sensor
Traceback (most recent call last):
  File "/usr/src/homeassistant/homeassistant/config_entries.py", line 452, in async_unload
    result = await component.async_unload_entry(hass, self)  # type: ignore
  File "/usr/src/homeassistant/homeassistant/components/sensor/__init__.py", line 210, in async_unload_entry
    return await component.async_unload_entry(entry)
  File "/usr/src/homeassistant/homeassistant/helpers/entity_component.py", line 177, in async_unload_entry
    raise ValueError("Config entry was never loaded!")
ValueError: Config entry was never loaded!
2022-01-11 17:57:18 ERROR (MainThread) [homeassistant.config_entries] Error unloading entry 192.168.1.24 for switch
Traceback (most recent call last):
  File "/usr/src/homeassistant/homeassistant/config_entries.py", line 452, in async_unload
    result = await component.async_unload_entry(hass, self)  # type: ignore
  File "/usr/src/homeassistant/homeassistant/components/switch/__init__.py", line 95, in async_unload_entry
    return await component.async_unload_entry(entry)
  File "/usr/src/homeassistant/homeassistant/helpers/entity_component.py", line 177, in async_unload_entry
    raise ValueError("Config entry was never loaded!")
ValueError: Config entry was never loaded!
2022-01-11 18:05:08 ERROR (MainThread) [homeassistant] Error doing job: Task exception was never retrieved
Traceback (most recent call last):
  File "/usr/local/lib/python3.9/site-packages/zigpy/device.py", line 265, in request
    result, msg = await self._application.request(
  File "/usr/local/lib/python3.9/site-packages/zigpy_znp/zigbee/application.py", line 453, in request
    return await self._send_request(
  File "/usr/local/lib/python3.9/site-packages/zigpy_znp/zigbee/application.py", line 1610, in _send_request
    raise DeliveryError(
zigpy.exceptions.DeliveryError: Request failed after 5 attempts: <Status.NWK_INVALID_REQUEST: 194>
2022-01-11 18:06:04 WARNING (MainThread) [homeassistant.components.zha.core.channels.base] [0xCC68:1:0x0001]: async_initialize: all attempts have failed: [DeliveryError('Request failed after 5 attempts: <Status.NWK_INVALID_REQUEST: 194>'), DeliveryError('Request failed after 5 attempts: <Status.NWK_INVALID_REQUEST: 194>'), DeliveryError('Request failed after 5 attempts: <Status.NWK_INVALID_REQUEST: 194>'), DeliveryError('Request failed after 5 attempts: <Status.NWK_INVALID_REQUEST: 194>')]
2022-01-11 18:06:04 WARNING (MainThread) [homeassistant.components.zha.core.channels.base] [0xCC68:1:0x0500]: async_initialize: all attempts have failed: [DeliveryError('Request failed after 5 attempts: <Status.NWK_INVALID_REQUEST: 194>'), DeliveryError('Request failed after 5 attempts: <Status.NWK_INVALID_REQUEST: 194>'), DeliveryError('Request failed after 5 attempts: <Status.NWK_INVALID_REQUEST: 194>'), DeliveryError('Request failed after 5 attempts: <Status.NWK_INVALID_REQUEST: 194>')]
2022-01-11 18:17:14 WARNING (MainThread) [custom_components.mail_and_packages.camera] Could not read camera Mail USPS Camera image from file: /config/custom_components/mail_and_packages/images/0f535031-f85c-427d-9b25-ec1913ae61fe.gif
2022-01-11 19:03:15 WARNING (MainThread) [custom_components.mail_and_packages.camera] Could not read camera Mail USPS Camera image from file: /config/custom_components/mail_and_packages/images/0f535031-f85c-427d-9b25-ec1913ae61fe.gif
2022-01-11 20:00:17 WARNING (MainThread) [homeassistant.helpers.entity] Update of weather.pirate_weather is taking over 10 seconds
2022-01-11 23:09:17 WARNING (MainThread) [custom_components.mail_and_packages.camera] Could not read camera Mail USPS Camera image from file: /config/custom_components/mail_and_packages/images/0f535031-f85c-427d-9b25-ec1913ae61fe.gif
2022-01-11 23:29:47 WARNING (MainThread) [custom_components.mail_and_packages.camera] Could not read camera Mail USPS Camera image from file: /config/custom_components/mail_and_packages/images/0f535031-f85c-427d-9b25-ec1913ae61fe.gif
2022-01-12 01:00:03 ERROR (MainThread) [homeassistant.components.speedtestdotnet] Error fetching speedtestdotnet data: Unable to connect to servers to test latency.
2022-01-12 05:30:00 ERROR (MainThread) [custom_components.auto_backup] Error during backup. Timeout on /backups/new/full request. There may be a backup already in progress.
2022-01-12 06:30:00 WARNING (MainThread) [homeassistant.helpers.service] Unable to find referenced entities switch.nodeid_21_switch
2022-01-12 06:30:01 WARNING (MainThread) [homeassistant.helpers.service] Unable to find referenced entities switch.nodeid_18_switch
2022-01-12 06:30:01 WARNING (MainThread) [homeassistant.helpers.service] Unable to find referenced entities switch.nodeid_19_switch
2022-01-12 06:30:01 WARNING (MainThread) [homeassistant.helpers.service] Unable to find referenced entities switch.nodeid_20_switch
2022-01-12 06:30:01 WARNING (MainThread) [homeassistant.helpers.service] Unable to find referenced entities switch.nodeid_20_switch
2022-01-12 06:30:03 WARNING (MainThread) [homeassistant.helpers.service] Unable to find referenced entities light.balcony_chandelier, light.kitchen_light_2, light.livingroom_receptacle_on_off, light.shelly_shbduo_1_d0cd10, light.shelly_shbduo_1_d1225f, switch.cabinet_lights_relay_2, switch.sink_light_relay_2
2022-01-12 08:24:08 WARNING (MainThread) [homeassistant.helpers.service] Unable to find referenced entities switch.ge_enbrighten_z_wave_plus_smart_switch
2022-01-12 09:37:05 ERROR (MainThread) [aiohttp.server] Error handling request
Traceback (most recent call last):
  File "/usr/local/lib/python3.9/site-packages/aiohttp/web_protocol.py", line 334, in data_received
    messages, upgraded, tail = self._request_parser.feed_data(data)
  File "aiohttp/_http_parser.pyx", line 551, in aiohttp._http_parser.HttpParser.feed_data
aiohttp.http_exceptions.BadStatusLine: 400, message="Bad status line 'Invalid method encountered'"
2022-01-12 09:37:06 ERROR (MainThread) [aiohttp.server] Error handling request
Traceback (most recent call last):
  File "/usr/local/lib/python3.9/site-packages/aiohttp/web_protocol.py", line 334, in data_received
    messages, upgraded, tail = self._request_parser.feed_data(data)
  File "aiohttp/_http_parser.pyx", line 551, in aiohttp._http_parser.HttpParser.feed_data
aiohttp.http_exceptions.BadStatusLine: 400, message="Bad status line 'Invalid method encountered'"
2022-01-12 09:37:06 ERROR (MainThread) [aiohttp.server] Error handling request
Traceback (most recent call last):
  File "/usr/local/lib/python3.9/site-packages/aiohttp/web_protocol.py", line 334, in data_received
    messages, upgraded, tail = self._request_parser.feed_data(data)
  File "aiohttp/_http_parser.pyx", line 551, in aiohttp._http_parser.HttpParser.feed_data
aiohttp.http_exceptions.BadStatusLine: 400, message="Bad status line 'Invalid method encountered'"
2022-01-12 09:37:06 ERROR (MainThread) [aiohttp.server] Error handling request
Traceback (most recent call last):
  File "/usr/local/lib/python3.9/site-packages/aiohttp/web_protocol.py", line 334, in data_received
    messages, upgraded, tail = self._request_parser.feed_data(data)
  File "aiohttp/_http_parser.pyx", line 551, in aiohttp._http_parser.HttpParser.feed_data
aiohttp.http_exceptions.BadStatusLine: 400, message="Bad status line 'Invalid method encountered'"
2022-01-12 09:37:10 ERROR (MainThread) [aiohttp.server] Error handling request
Traceback (most recent call last):
  File "/usr/local/lib/python3.9/site-packages/aiohttp/web_protocol.py", line 334, in data_received
    messages, upgraded, tail = self._request_parser.feed_data(data)
  File "aiohttp/_http_parser.pyx", line 551, in aiohttp._http_parser.HttpParser.feed_data
aiohttp.http_exceptions.BadStatusLine: 400, message="Bad status line 'Invalid method encountered'"
2022-01-12 09:37:11 ERROR (MainThread) [aiohttp.server] Error handling request
Traceback (most recent call last):
  File "/usr/local/lib/python3.9/site-packages/aiohttp/web_protocol.py", line 334, in data_received
    messages, upgraded, tail = self._request_parser.feed_data(data)
  File "aiohttp/_http_parser.pyx", line 551, in aiohttp._http_parser.HttpParser.feed_data
aiohttp.http_exceptions.BadStatusLine: 400, message="Bad status line 'Invalid method encountered'"
2022-01-12 09:37:11 ERROR (MainThread) [aiohttp.server] Error handling request
Traceback (most recent call last):
  File "/usr/local/lib/python3.9/site-packages/aiohttp/web_protocol.py", line 334, in data_received
    messages, upgraded, tail = self._request_parser.feed_data(data)
  File "aiohttp/_http_parser.pyx", line 551, in aiohttp._http_parser.HttpParser.feed_data
aiohttp.http_exceptions.BadStatusLine: 400, message="Bad status line 'Invalid method encountered'"
2022-01-12 09:37:11 ERROR (MainThread) [aiohttp.server] Error handling request
Traceback (most recent call last):
  File "/usr/local/lib/python3.9/site-packages/aiohttp/web_protocol.py", line 334, in data_received
    messages, upgraded, tail = self._request_parser.feed_data(data)
  File "aiohttp/_http_parser.pyx", line 551, in aiohttp._http_parser.HttpParser.feed_data
aiohttp.http_exceptions.BadStatusLine: 400, message="Bad status line 'Invalid method encountered'"
2022-01-12 09:37:15 ERROR (MainThread) [aiohttp.server] Error handling request
Traceback (most recent call last):
  File "/usr/local/lib/python3.9/site-packages/aiohttp/web_protocol.py", line 334, in data_received
    messages, upgraded, tail = self._request_parser.feed_data(data)
  File "aiohttp/_http_parser.pyx", line 551, in aiohttp._http_parser.HttpParser.feed_data
aiohttp.http_exceptions.BadStatusLine: 400, message="Bad status line 'Invalid method encountered'"
2022-01-12 09:37:16 ERROR (MainThread) [aiohttp.server] Error handling request
Traceback (most recent call last):
  File "/usr/local/lib/python3.9/site-packages/aiohttp/web_protocol.py", line 334, in data_received
    messages, upgraded, tail = self._request_parser.feed_data(data)
  File "aiohttp/_http_parser.pyx", line 551, in aiohttp._http_parser.HttpParser.feed_data
aiohttp.http_exceptions.BadStatusLine: 400, message="Bad status line 'Invalid method encountered'"
2022-01-12 09:37:16 ERROR (MainThread) [aiohttp.server] Error handling request
Traceback (most recent call last):
  File "/usr/local/lib/python3.9/site-packages/aiohttp/web_protocol.py", line 334, in data_received
    messages, upgraded, tail = self._request_parser.feed_data(data)
  File "aiohttp/_http_parser.pyx", line 551, in aiohttp._http_parser.HttpParser.feed_data
aiohttp.http_exceptions.BadStatusLine: 400, message="Bad status line 'Invalid method encountered'"
2022-01-12 09:37:16 ERROR (MainThread) [aiohttp.server] Error handling request
Traceback (most recent call last):
  File "/usr/local/lib/python3.9/site-packages/aiohttp/web_protocol.py", line 334, in data_received
    messages, upgraded, tail = self._request_parser.feed_data(data)
  File "aiohttp/_http_parser.pyx", line 551, in aiohttp._http_parser.HttpParser.feed_data
aiohttp.http_exceptions.BadStatusLine: 400, message="Bad status line 'Invalid method encountered'"
2022-01-12 09:37:20 ERROR (MainThread) [aiohttp.server] Error handling request
Traceback (most recent call last):
  File "/usr/local/lib/python3.9/site-packages/aiohttp/web_protocol.py", line 334, in data_received
    messages, upgraded, tail = self._request_parser.feed_data(data)
  File "aiohttp/_http_parser.pyx", line 551, in aiohttp._http_parser.HttpParser.feed_data
aiohttp.http_exceptions.BadStatusLine: 400, message="Bad status line 'Invalid method encountered'"
2022-01-12 09:37:21 ERROR (MainThread) [aiohttp.server] Error handling request
Traceback (most recent call last):
  File "/usr/local/lib/python3.9/site-packages/aiohttp/web_protocol.py", line 334, in data_received
    messages, upgraded, tail = self._request_parser.feed_data(data)
  File "aiohttp/_http_parser.pyx", line 551, in aiohttp._http_parser.HttpParser.feed_data
aiohttp.http_exceptions.BadStatusLine: 400, message="Bad status line 'Invalid method encountered'"
2022-01-12 09:37:21 ERROR (MainThread) [aiohttp.server] Error handling request
Traceback (most recent call last):
  File "/usr/local/lib/python3.9/site-packages/aiohttp/web_protocol.py", line 334, in data_received
    messages, upgraded, tail = self._request_parser.feed_data(data)
  File "aiohttp/_http_parser.pyx", line 551, in aiohttp._http_parser.HttpParser.feed_data
aiohttp.http_exceptions.BadStatusLine: 400, message="Bad status line 'Invalid method encountered'"
2022-01-12 09:37:21 ERROR (MainThread) [aiohttp.server] Error handling request
Traceback (most recent call last):
  File "/usr/local/lib/python3.9/site-packages/aiohttp/web_protocol.py", line 334, in data_received
    messages, upgraded, tail = self._request_parser.feed_data(data)
  File "aiohttp/_http_parser.pyx", line 551, in aiohttp._http_parser.HttpParser.feed_data
aiohttp.http_exceptions.BadStatusLine: 400, message="Bad status line 'Invalid method encountered'"
2022-01-12 09:37:35 ERROR (MainThread) [aiohttp.server] Error handling request
Traceback (most recent call last):
  File "/usr/local/lib/python3.9/site-packages/aiohttp/web_protocol.py", line 334, in data_received
    messages, upgraded, tail = self._request_parser.feed_data(data)
  File "aiohttp/_http_parser.pyx", line 551, in aiohttp._http_parser.HttpParser.feed_data
aiohttp.http_exceptions.BadStatusLine: 400, message="Bad status line 'Invalid method encountered'"
2022-01-12 09:37:36 ERROR (MainThread) [aiohttp.server] Error handling request
Traceback (most recent call last):
  File "/usr/local/lib/python3.9/site-packages/aiohttp/web_protocol.py", line 334, in data_received
    messages, upgraded, tail = self._request_parser.feed_data(data)
  File "aiohttp/_http_parser.pyx", line 551, in aiohttp._http_parser.HttpParser.feed_data
aiohttp.http_exceptions.BadStatusLine: 400, message="Bad status line 'Invalid method encountered'"
2022-01-12 09:37:36 ERROR (MainThread) [aiohttp.server] Error handling request
Traceback (most recent call last):
  File "/usr/local/lib/python3.9/site-packages/aiohttp/web_protocol.py", line 334, in data_received
    messages, upgraded, tail = self._request_parser.feed_data(data)
  File "aiohttp/_http_parser.pyx", line 551, in aiohttp._http_parser.HttpParser.feed_data
aiohttp.http_exceptions.BadStatusLine: 400, message="Bad status line 'Invalid method encountered'"
2022-01-12 09:37:36 ERROR (MainThread) [aiohttp.server] Error handling request
Traceback (most recent call last):
  File "/usr/local/lib/python3.9/site-packages/aiohttp/web_protocol.py", line 334, in data_received
    messages, upgraded, tail = self._request_parser.feed_data(data)
  File "aiohttp/_http_parser.pyx", line 551, in aiohttp._http_parser.HttpParser.feed_data
aiohttp.http_exceptions.BadStatusLine: 400, message="Bad status line 'Invalid method encountered'"
2022-01-12 09:37:50 ERROR (MainThread) [aiohttp.server] Error handling request
Traceback (most recent call last):
  File "/usr/local/lib/python3.9/site-packages/aiohttp/web_protocol.py", line 334, in data_received
    messages, upgraded, tail = self._request_parser.feed_data(data)
  File "aiohttp/_http_parser.pyx", line 551, in aiohttp._http_parser.HttpParser.feed_data
aiohttp.http_exceptions.BadStatusLine: 400, message="Bad status line 'Invalid method encountered'"
2022-01-12 09:37:51 ERROR (MainThread) [aiohttp.server] Error handling request
Traceback (most recent call last):
  File "/usr/local/lib/python3.9/site-packages/aiohttp/web_protocol.py", line 334, in data_received
    messages, upgraded, tail = self._request_parser.feed_data(data)
  File "aiohttp/_http_parser.pyx", line 551, in aiohttp._http_parser.HttpParser.feed_data
aiohttp.http_exceptions.BadStatusLine: 400, message="Bad status line 'Invalid method encountered'"
2022-01-12 09:37:51 ERROR (MainThread) [aiohttp.server] Error handling request
Traceback (most recent call last):
  File "/usr/local/lib/python3.9/site-packages/aiohttp/web_protocol.py", line 334, in data_received
    messages, upgraded, tail = self._request_parser.feed_data(data)
  File "aiohttp/_http_parser.pyx", line 551, in aiohttp._http_parser.HttpParser.feed_data
aiohttp.http_exceptions.BadStatusLine: 400, message="Bad status line 'Invalid method encountered'"
2022-01-12 09:37:51 ERROR (MainThread) [aiohttp.server] Error handling request
Traceback (most recent call last):
  File "/usr/local/lib/python3.9/site-packages/aiohttp/web_protocol.py", line 334, in data_received
    messages, upgraded, tail = self._request_parser.feed_data(data)
  File "aiohttp/_http_parser.pyx", line 551, in aiohttp._http_parser.HttpParser.feed_data
aiohttp.http_exceptions.BadStatusLine: 400, message="Bad status line 'Invalid method encountered'"
2022-01-12 09:38:20 ERROR (MainThread) [aiohttp.server] Error handling request
Traceback (most recent call last):
  File "/usr/local/lib/python3.9/site-packages/aiohttp/web_protocol.py", line 334, in data_received
    messages, upgraded, tail = self._request_parser.feed_data(data)
  File "aiohttp/_http_parser.pyx", line 551, in aiohttp._http_parser.HttpParser.feed_data
aiohttp.http_exceptions.BadStatusLine: 400, message="Bad status line 'Invalid method encountered'"
2022-01-12 09:38:21 ERROR (MainThread) [aiohttp.server] Error handling request
Traceback (most recent call last):
  File "/usr/local/lib/python3.9/site-packages/aiohttp/web_protocol.py", line 334, in data_received
    messages, upgraded, tail = self._request_parser.feed_data(data)
  File "aiohttp/_http_parser.pyx", line 551, in aiohttp._http_parser.HttpParser.feed_data
aiohttp.http_exceptions.BadStatusLine: 400, message="Bad status line 'Invalid method encountered'"
2022-01-12 09:38:21 ERROR (MainThread) [aiohttp.server] Error handling request
Traceback (most recent call last):
  File "/usr/local/lib/python3.9/site-packages/aiohttp/web_protocol.py", line 334, in data_received
    messages, upgraded, tail = self._request_parser.feed_data(data)
  File "aiohttp/_http_parser.pyx", line 551, in aiohttp._http_parser.HttpParser.feed_data
aiohttp.http_exceptions.BadStatusLine: 400, message="Bad status line 'Invalid method encountered'"
2022-01-12 09:38:21 ERROR (MainThread) [aiohttp.server] Error handling request
Traceback (most recent call last):
  File "/usr/local/lib/python3.9/site-packages/aiohttp/web_protocol.py", line 334, in data_received
    messages, upgraded, tail = self._request_parser.feed_data(data)
  File "aiohttp/_http_parser.pyx", line 551, in aiohttp._http_parser.HttpParser.feed_data
aiohttp.http_exceptions.BadStatusLine: 400, message="Bad status line 'Invalid method encountered'"
2022-01-12 09:39:20 ERROR (MainThread) [aiohttp.server] Error handling request
Traceback (most recent call last):
  File "/usr/local/lib/python3.9/site-packages/aiohttp/web_protocol.py", line 334, in data_received
    messages, upgraded, tail = self._request_parser.feed_data(data)
  File "aiohttp/_http_parser.pyx", line 551, in aiohttp._http_parser.HttpParser.feed_data
aiohttp.http_exceptions.BadStatusLine: 400, message="Bad status line 'Invalid method encountered'"
2022-01-12 09:39:21 ERROR (MainThread) [aiohttp.server] Error handling request
Traceback (most recent call last):
  File "/usr/local/lib/python3.9/site-packages/aiohttp/web_protocol.py", line 334, in data_received
    messages, upgraded, tail = self._request_parser.feed_data(data)
  File "aiohttp/_http_parser.pyx", line 551, in aiohttp._http_parser.HttpParser.feed_data
aiohttp.http_exceptions.BadStatusLine: 400, message="Bad status line 'Invalid method encountered'"
2022-01-12 09:39:21 ERROR (MainThread) [aiohttp.server] Error handling request
Traceback (most recent call last):
  File "/usr/local/lib/python3.9/site-packages/aiohttp/web_protocol.py", line 334, in data_received
    messages, upgraded, tail = self._request_parser.feed_data(data)
  File "aiohttp/_http_parser.pyx", line 551, in aiohttp._http_parser.HttpParser.feed_data
aiohttp.http_exceptions.BadStatusLine: 400, message="Bad status line 'Invalid method encountered'"
2022-01-12 09:39:21 ERROR (MainThread) [aiohttp.server] Error handling request
Traceback (most recent call last):
  File "/usr/local/lib/python3.9/site-packages/aiohttp/web_protocol.py", line 334, in data_received
    messages, upgraded, tail = self._request_parser.feed_data(data)
  File "aiohttp/_http_parser.pyx", line 551, in aiohttp._http_parser.HttpParser.feed_data
aiohttp.http_exceptions.BadStatusLine: 400, message="Bad status line 'Invalid method encountered'"
2022-01-12 09:40:20 ERROR (MainThread) [aiohttp.server] Error handling request
Traceback (most recent call last):
  File "/usr/local/lib/python3.9/site-packages/aiohttp/web_protocol.py", line 334, in data_received
    messages, upgraded, tail = self._request_parser.feed_data(data)
  File "aiohttp/_http_parser.pyx", line 551, in aiohttp._http_parser.HttpParser.feed_data
aiohttp.http_exceptions.BadStatusLine: 400, message="Bad status line 'Invalid method encountered'"
2022-01-12 09:40:21 ERROR (MainThread) [aiohttp.server] Error handling request
Traceback (most recent call last):
  File "/usr/local/lib/python3.9/site-packages/aiohttp/web_protocol.py", line 334, in data_received
    messages, upgraded, tail = self._request_parser.feed_data(data)
  File "aiohttp/_http_parser.pyx", line 551, in aiohttp._http_parser.HttpParser.feed_data
aiohttp.http_exceptions.BadStatusLine: 400, message="Bad status line 'Invalid method encountered'"
2022-01-12 09:40:21 ERROR (MainThread) [aiohttp.server] Error handling request
Traceback (most recent call last):
  File "/usr/local/lib/python3.9/site-packages/aiohttp/web_protocol.py", line 334, in data_received
    messages, upgraded, tail = self._request_parser.feed_data(data)
  File "aiohttp/_http_parser.pyx", line 551, in aiohttp._http_parser.HttpParser.feed_data
aiohttp.http_exceptions.BadStatusLine: 400, message="Bad status line 'Invalid method encountered'"
2022-01-12 09:40:21 ERROR (MainThread) [aiohttp.server] Error handling request
Traceback (most recent call last):
  File "/usr/local/lib/python3.9/site-packages/aiohttp/web_protocol.py", line 334, in data_received
    messages, upgraded, tail = self._request_parser.feed_data(data)
  File "aiohttp/_http_parser.pyx", line 551, in aiohttp._http_parser.HttpParser.feed_data
aiohttp.http_exceptions.BadStatusLine: 400, message="Bad status line 'Invalid method encountered'"
2022-01-12 09:42:20 ERROR (MainThread) [aiohttp.server] Error handling request
Traceback (most recent call last):
  File "/usr/local/lib/python3.9/site-packages/aiohttp/web_protocol.py", line 334, in data_received
    messages, upgraded, tail = self._request_parser.feed_data(data)
  File "aiohttp/_http_parser.pyx", line 551, in aiohttp._http_parser.HttpParser.feed_data
aiohttp.http_exceptions.BadStatusLine: 400, message="Bad status line 'Invalid method encountered'"
2022-01-12 09:42:21 ERROR (MainThread) [aiohttp.server] Error handling request
Traceback (most recent call last):
  File "/usr/local/lib/python3.9/site-packages/aiohttp/web_protocol.py", line 334, in data_received
    messages, upgraded, tail = self._request_parser.feed_data(data)
  File "aiohttp/_http_parser.pyx", line 551, in aiohttp._http_parser.HttpParser.feed_data
aiohttp.http_exceptions.BadStatusLine: 400, message="Bad status line 'Invalid method encountered'"
2022-01-12 09:42:21 ERROR (MainThread) [aiohttp.server] Error handling request
Traceback (most recent call last):
  File "/usr/local/lib/python3.9/site-packages/aiohttp/web_protocol.py", line 334, in data_received
    messages, upgraded, tail = self._request_parser.feed_data(data)
  File "aiohttp/_http_parser.pyx", line 551, in aiohttp._http_parser.HttpParser.feed_data
aiohttp.http_exceptions.BadStatusLine: 400, message="Bad status line 'Invalid method encountered'"
2022-01-12 09:42:21 ERROR (MainThread) [aiohttp.server] Error handling request
Traceback (most recent call last):
  File "/usr/local/lib/python3.9/site-packages/aiohttp/web_protocol.py", line 334, in data_received
    messages, upgraded, tail = self._request_parser.feed_data(data)
  File "aiohttp/_http_parser.pyx", line 551, in aiohttp._http_parser.HttpParser.feed_data
aiohttp.http_exceptions.BadStatusLine: 400, message="Bad status line 'Invalid method encountered'"
2022-01-12 09:45:20 ERROR (MainThread) [aiohttp.server] Error handling request
Traceback (most recent call last):
  File "/usr/local/lib/python3.9/site-packages/aiohttp/web_protocol.py", line 334, in data_received
    messages, upgraded, tail = self._request_parser.feed_data(data)
  File "aiohttp/_http_parser.pyx", line 551, in aiohttp._http_parser.HttpParser.feed_data
aiohttp.http_exceptions.BadStatusLine: 400, message="Bad status line 'Invalid method encountered'"
2022-01-12 09:45:21 ERROR (MainThread) [aiohttp.server] Error handling request
Traceback (most recent call last):
  File "/usr/local/lib/python3.9/site-packages/aiohttp/web_protocol.py", line 334, in data_received
    messages, upgraded, tail = self._request_parser.feed_data(data)
  File "aiohttp/_http_parser.pyx", line 551, in aiohttp._http_parser.HttpParser.feed_data
aiohttp.http_exceptions.BadStatusLine: 400, message="Bad status line 'Invalid method encountered'"
2022-01-12 09:45:21 ERROR (MainThread) [aiohttp.server] Error handling request
Traceback (most recent call last):
  File "/usr/local/lib/python3.9/site-packages/aiohttp/web_protocol.py", line 334, in data_received
    messages, upgraded, tail = self._request_parser.feed_data(data)
  File "aiohttp/_http_parser.pyx", line 551, in aiohttp._http_parser.HttpParser.feed_data
aiohttp.http_exceptions.BadStatusLine: 400, message="Bad status line 'Invalid method encountered'"
2022-01-12 09:45:21 ERROR (MainThread) [aiohttp.server] Error handling request
Traceback (most recent call last):
  File "/usr/local/lib/python3.9/site-packages/aiohttp/web_protocol.py", line 334, in data_received
    messages, upgraded, tail = self._request_parser.feed_data(data)
  File "aiohttp/_http_parser.pyx", line 551, in aiohttp._http_parser.HttpParser.feed_data
aiohttp.http_exceptions.BadStatusLine: 400, message="Bad status line 'Invalid method encountered'"
2022-01-12 10:32:49 WARNING (MainThread) [custom_components.mail_and_packages.camera] Could not read camera Mail USPS Camera image from file: /config/custom_components/mail_and_packages/images/bf5d8ede-eb8d-4e3a-9184-6a4ed2af9f2d.gif
2022-01-12 11:06:05 WARNING (MainThread) [homeassistant.helpers.service] Unable to find referenced entities switch.ge_enbrighten_z_wave_plus_smart_switch
2022-01-12 11:11:05 WARNING (MainThread) [homeassistant.helpers.service] Unable to find referenced entities switch.ge_enbrighten_z_wave_plus_smart_switch
2022-01-12 12:38:31 WARNING (MainThread) [homeassistant.helpers.service] Unable to find referenced entities switch.ge_enbrighten_z_wave_plus_smart_switch
2022-01-12 14:12:04 WARNING (MainThread) [homeassistant.helpers.entity] Update of sensor.pirateweather_daily_summary is taking over 10 seconds
2022-01-12 14:36:33 WARNING (MainThread) [homeassistant.helpers.service] Unable to find referenced entities switch.ge_enbrighten_z_wave_plus_smart_switch
2022-01-12 15:09:22 WARNING (MainThread) [homeassistant.helpers.service] Unable to find referenced entities switch.ge_enbrighten_z_wave_plus_smart_switch
2022-01-12 15:11:23 ERROR (SyncWorker_11) [homeassistant.components.life360.device_tracker] get_circles: CommError: HTTPSConnectionPool(host='api.life360.com', port=443): Max retries exceeded with url: /v3/circles.json (Caused by NewConnectionError('<urllib3.connection.HTTPSConnection object at 0x7fb99fb13370>: Failed to establish a new connection: [Errno -3] Try again'))
2022-01-12 15:11:28 ERROR (MainThread) [homeassistant.components.uptimerobot] Error fetching uptimerobot data: Request timeout for 'https://api.uptimerobot.com/v2/getMonitors'
2022-01-12 15:16:20 WARNING (MainThread) [homeassistant.components.media_player] Updating webostv media_player took longer than the scheduled update interval 0:00:10
2022-01-12 15:17:26 WARNING (MainThread) [homeassistant.components.sensor] Updating garbage_collection sensor took longer than the scheduled update interval 0:00:10
2022-01-12 15:17:26 WARNING (MainThread) [homeassistant.components.sensor] Updating garbage_collection sensor took longer than the scheduled update interval 0:00:10
2022-01-12 15:17:30 WARNING (MainThread) [homeassistant.helpers.entity] Updating state for sensor.deck_door_power (<class 'homeassistant.components.zha.sensor.Battery'>) took 0.579 seconds. Please create a bug report at https://github.com/home-assistant/core/issues?q=is%3Aopen+is%3Aissue+label%3A%22integration%3A+zha%22
2022-01-12 15:17:50 WARNING (MainThread) [homeassistant.components.camera] Updating mail_and_packages camera took longer than the scheduled update interval 0:00:30
2022-01-12 15:17:56 ERROR (MainThread) [homeassistant.components.uptimerobot] Error fetching uptimerobot data: Request timeout for 'https://api.uptimerobot.com/v2/getMonitors'
2022-01-12 15:17:59 WARNING (MainThread) [homeassistant.components.media_player] Updating webostv media_player took longer than the scheduled update interval 0:00:10
2022-01-12 15:18:00 ERROR (MainThread) [homeassistant] Error doing job: Task exception was never retrieved
Traceback (most recent call last):
  File "/usr/local/lib/python3.9/site-packages/aiohttp/http_websocket.py", line 676, in ping
    await self._send_frame(message, WSMsgType.PING)
  File "/usr/local/lib/python3.9/site-packages/aiohttp/http_websocket.py", line 653, in _send_frame
    self._write(header + message)
  File "/usr/local/lib/python3.9/site-packages/aiohttp/http_websocket.py", line 663, in _write
    raise ConnectionResetError("Cannot write to closing transport")
ConnectionResetError: Cannot write to closing transport
2022-01-12 15:18:05 WARNING (MainThread) [homeassistant.helpers.entity] Updating state for sensor.garbage_day (<class 'custom_components.garbage_collection.sensor.GarbageCollection'>) took 0.595 seconds. Please report it to the custom component author.
2022-01-12 15:18:20 ERROR (MainThread) [homeassistant.components.synology_dsm] Timeout fetching 1850PDN814708_cameras data
2022-01-12 15:18:23 ERROR (MainThread) [homeassistant.components.openweathermap.weather_update_coordinator] Timeout fetching openweathermap data
2022-01-12 15:18:33 WARNING (MainThread) [homeassistant.components.http.ban] Login attempt or request with invalid authentication from Eds-DeskTop.Office (192.168.1.166). (Mozilla/5.0 (Windows NT 10.0; Win64; x64; rv:96.0) Gecko/20100101 Firefox/96.0)
2022-01-12 15:18:48 WARNING (MainThread) [homeassistant.helpers.entity] Updating state for sensor.aerator_temperature (<class 'homeassistant.components.esphome.sensor.EsphomeSensor'>) took 0.600 seconds. Please create a bug report at https://github.com/home-assistant/core/issues?q=is%3Aopen+is%3Aissue+label%3A%22integration%3A+esphome%22
2022-01-12 15:18:49 WARNING (MainThread) [homeassistant.helpers.entity] Updating state for sensor.aerator_wifi_signal (<class 'homeassistant.components.esphome.sensor.EsphomeSensor'>) took 0.410 seconds. Please create a bug report at https://github.com/home-assistant/core/issues?q=is%3Aopen+is%3Aissue+label%3A%22integration%3A+esphome%22
2022-01-12 15:19:04 WARNING (MainThread) [homeassistant.helpers.entity] Updating state for binary_sensor.office_protect (<class 'homeassistant.components.homekit_controller.binary_sensor.HomeKitSmokeSensor'>) took 0.491 seconds. Please create a bug report at https://github.com/home-assistant/core/issues?q=is%3Aopen+is%3Aissue+label%3A%22integration%3A+homekit_controller%22
2022-01-12 15:19:05 WARNING (MainThread) [homeassistant.helpers.entity] Updating state for binary_sensor.office_protect_2 (<class 'homeassistant.components.homekit_controller.binary_sensor.HomeKitCarbonMonoxideSensor'>) took 1.168 seconds. Please create a bug report at https://github.com/home-assistant/core/issues?q=is%3Aopen+is%3Aissue+label%3A%22integration%3A+homekit_controller%22
2022-01-12 15:19:06 WARNING (MainThread) [homeassistant.helpers.entity] Updating state for switch.back_door_doorbell_2 (<class 'homeassistant.components.homekit_controller.switch.HomeKitSwitch'>) took 0.543 seconds. Please create a bug report at https://github.com/home-assistant/core/issues?q=is%3Aopen+is%3Aissue+label%3A%22integration%3A+homekit_controller%22
2022-01-12 15:19:07 WARNING (MainThread) [homeassistant.helpers.entity] Updating state for switch.home_occupied (<class 'homeassistant.components.homekit_controller.switch.HomeKitSwitch'>) took 0.427 seconds. Please create a bug report at https://github.com/home-assistant/core/issues?q=is%3Aopen+is%3Aissue+label%3A%22integration%3A+homekit_controller%22
2022-01-12 15:19:14 WARNING (MainThread) [homeassistant.helpers.entity] Updating state for sensor.dining_room_heat_on_today (<class 'homeassistant.components.history_stats.sensor.HistoryStatsSensor'>) took 0.455 seconds. Please create a bug report at https://github.com/home-assistant/core/issues?q=is%3Aopen+is%3Aissue+label%3A%22integration%3A+history_stats%22
2022-01-12 15:19:17 ERROR (influxdb) [homeassistant.components.influxdb] Cannot connect to InfluxDB due to 'HTTPConnectionPool(host='a0d7b954-influxdb', port=8086): Max retries exceeded with url: /write?db=homeassistant (Caused by NewConnectionError('<urllib3.connection.HTTPConnection object at 0x7fb9859ca640>: Failed to establish a new connection: [Errno -3] Try again'))'. Please check that the provided connection details (host, port, etc.) are correct and that your InfluxDB server is running and accessible.
2022-01-12 15:19:19 WARNING (MainThread) [homeassistant.helpers.entity] Updating state for sensor.master_bedroom_heat_on_today (<class 'homeassistant.components.history_stats.sensor.HistoryStatsSensor'>) took 1.564 seconds. Please create a bug report at https://github.com/home-assistant/core/issues?q=is%3Aopen+is%3Aissue+label%3A%22integration%3A+history_stats%22
2022-01-12 15:19:25 WARNING (MainThread) [homeassistant.components.sensor] Updating history_stats sensor took longer than the scheduled update interval 0:00:30
2022-01-12 15:19:25 WARNING (influxdb) [homeassistant.components.influxdb] Catching up, dropped 62 old events.
2022-01-12 15:19:29 WARNING (MainThread) [homeassistant.components.sensor] Updating garbage_collection sensor took longer than the scheduled update interval 0:00:10
2022-01-12 15:19:30 WARNING (MainThread) [homeassistant.components.sensor] Updating garbage_collection sensor took longer than the scheduled update interval 0:00:10
2022-01-12 15:19:31 WARNING (MainThread) [homeassistant.components.sensor] Updating auto_backup sensor took longer than the scheduled update interval 0:00:30
2022-01-12 15:19:31 WARNING (MainThread) [homeassistant.components.sensor] Updating version sensor took longer than the scheduled update interval 0:00:30
2022-01-12 15:19:33 WARNING (MainThread) [homeassistant.components.sensor] Updating sql sensor took longer than the scheduled update interval 0:00:30
2022-01-12 15:19:33 WARNING (MainThread) [homeassistant.components.sensor] Updating ecobee sensor took longer than the scheduled update interval 0:00:30
2022-01-12 15:19:33 WARNING (MainThread) [homeassistant.components.sensor] Updating local_ip sensor took longer than the scheduled update interval 0:00:30
2022-01-12 15:19:53 WARNING (MainThread) [homeassistant.helpers.template] Template warning: 'float' got invalid input 'unavailable' when rendering template '{{ (states('sensor.openweathermap_wind_speed') | float * 2.2369) | round(2) | default(0, true) }}' but no default was specified. Currently 'float' will return '0', however this template will fail to render in Home Assistant core 2022.1
2022-01-12 15:19:53 WARNING (MainThread) [homeassistant.helpers.template] Template warning: 'float' got invalid input 'unavailable' when rendering template '{{ (states('sensor.openweathermap_rain') | float / 25.4) | round(2) | default(0, true) }}' but no default was specified. Currently 'float' will return '0', however this template will fail to render in Home Assistant core 2022.1
2022-01-12 15:19:53 WARNING (MainThread) [homeassistant.helpers.template] Template warning: 'float' got invalid input 'unavailable' when rendering template '{{ (states('sensor.openweathermap_snow') | float / 25.4) | round(2) | default(0, true) }}' but no default was specified. Currently 'float' will return '0', however this template will fail to render in Home Assistant core 2022.1
2022-01-12 15:20:03 ERROR (influxdb) [homeassistant.components.influxdb] Resumed, lost 1 events.
2022-01-12 15:20:03 ERROR (MainThread) [homeassistant] Error doing job: Task exception was never retrieved
Traceback (most recent call last):
  File "/usr/local/lib/python3.9/site-packages/zigpy_znp/api.py", line 826, in request
    response = await response_future
asyncio.exceptions.CancelledError

During handling of the above exception, another exception occurred:

Traceback (most recent call last):
  File "/usr/local/lib/python3.9/site-packages/zigpy_znp/api.py", line 865, in request_callback_rsp
    await self.request(request, **response_params)
  File "/usr/local/lib/python3.9/site-packages/zigpy_znp/api.py", line 826, in request
    response = await response_future
  File "/usr/local/lib/python3.9/site-packages/async_timeout/__init__.py", line 128, in __aexit__
    self._do_exit(exc_type)
  File "/usr/local/lib/python3.9/site-packages/async_timeout/__init__.py", line 203, in _do_exit
    raise asyncio.TimeoutError
asyncio.exceptions.TimeoutError
2022-01-12 15:20:03 WARNING (MainThread) [homeassistant.helpers.entity] Update of media_player.mancave_tv is taking over 10 seconds
2022-01-12 15:20:03 WARNING (MainThread) [homeassistant.components.switch] Updating alexa_media switch took longer than the scheduled update interval 0:00:30
2022-01-12 15:20:03 WARNING (MainThread) [homeassistant.components.binary_sensor] Updating workday binary_sensor took longer than the scheduled update interval 0:00:30
2022-01-12 15:20:03 WARNING (MainThread) [homeassistant.components.weather] Updating pirateweather weather took longer than the scheduled update interval 0:00:30
2022-01-12 15:20:03 WARNING (MainThread) [homeassistant.components.weather] Updating ecobee weather took longer than the scheduled update interval 0:00:30
2022-01-12 15:20:03 WARNING (MainThread) [homeassistant.components.media_player] Updating webostv media_player took longer than the scheduled update interval 0:00:10
2022-01-12 15:20:03 WARNING (MainThread) [homeassistant.components.climate] Updating ecobee climate took longer than the scheduled update interval 0:01:00
2022-01-12 15:20:03 WARNING (MainThread) [homeassistant.components.homekit_controller.connection] HomeKit controller update skipped as previous poll still in flight: 06:DF:BA:A6:37:9F
2022-01-12 15:20:03 WARNING (MainThread) [homeassistant.components.sensor] Updating command_line sensor took longer than the scheduled update interval 0:01:00
2022-01-12 15:20:04 WARNING (MainThread) [homeassistant.components.calendar] Updating garbage_collection calendar took longer than the scheduled update interval 0:01:00
2022-01-12 15:20:04 WARNING (MainThread) [homeassistant.components.sensor] Updating time_date sensor took longer than the scheduled update interval 0:00:30
2022-01-12 15:20:04 WARNING (MainThread) [homeassistant.components.sensor] Updating auto_backup sensor took longer than the scheduled update interval 0:00:30
2022-01-12 15:20:04 WARNING (MainThread) [homeassistant.components.sensor] Updating version sensor took longer than the scheduled update interval 0:00:30
2022-01-12 15:20:04 WARNING (MainThread) [homeassistant.components.sensor] Updating sql sensor took longer than the scheduled update interval 0:00:30
2022-01-12 15:20:04 WARNING (MainThread) [homeassistant.components.sensor] Updating ecobee sensor took longer than the scheduled update interval 0:00:30
2022-01-12 15:20:04 WARNING (MainThread) [homeassistant.components.sensor] Updating local_ip sensor took longer than the scheduled update interval 0:00:30
2022-01-12 15:20:05 ERROR (MainThread) [homeassistant.components.accuweather] Timeout fetching accuweather data
2022-01-12 15:20:06 WARNING (MainThread) [homeassistant.components.http.ban] Login attempt or request with invalid authentication from Eds-DeskTop.Office (192.168.1.166). (Mozilla/5.0 (Windows NT 10.0; Win64; x64; rv:96.0) Gecko/20100101 Firefox/96.0)
2022-01-12 15:20:06 WARNING (MainThread) [homeassistant.components.http.ban] Login attempt or request with invalid authentication from Eds-DeskTop.Office (192.168.1.166). (Mozilla/5.0 (Windows NT 10.0; Win64; x64; rv:96.0) Gecko/20100101 Firefox/96.0)
2022-01-12 15:20:07 WARNING (MainThread) [homeassistant.components.media_player] Updating webostv media_player took longer than the scheduled update interval 0:00:10
2022-01-12 15:20:07 WARNING (MainThread) [homeassistant.components.websocket_api.http.connection] [140435094401520] Disconnected: Received non-Text message.
2022-01-12 15:20:08 ERROR (MainThread) [homeassistant.components.upnp] Timeout fetching Netgear R6400 v2:EWVisualArts data
2022-01-12 15:20:08 WARNING (MainThread) [homeassistant.helpers.template] Template warning: 'int' got invalid input 'unavailable' when rendering template '{% set time = states.sensor.netgear_r6400_v2_ewvisualarts_uptime.state | int | int %}
{%- if time < 60 -%}
  Just restarted .....
  {% else %}
    {% set minutes = (time // 60) | int %}
    {% set hours = (minutes // 60) %}
    {% set days = (hours // 24) %}
    {% set weeks = (days // 7) %}

    {% set minutes = (minutes % 60) %}
    {% set hours =  (hours % 24) %}
    {% set days = (days % 7) %}

    {% macro phrase(value, name) %}
              {%- set value = value %}
              {%- set end = 's' if value > 1 else '' %}
              {{- '{} {}{}'.format(value, name, end) if value | int > 0 else '' }}
    {%- endmacro %}

    {% set text = [ phrase(weeks, 'wk'), phrase(days, 'day'), phrase(hours, 'hr'), phrase(minutes, 'min') ] | select('!=','') | list | join(', ') %}
    {% set last_comma = text.rfind(',') %}
    {% if last_comma != -1 %}
      {% set text = text[:last_comma] + '' + text[last_comma + 1:] %}
    {% endif %}

  {{ text }}

  {% endif %}' but no default was specified. Currently 'int' will return '0', however this template will fail to render in Home Assistant core 2022.1
2022-01-12 18:00:10 ERROR (MainThread) [homeassistant.components.accuweather] Unexpected error fetching accuweather data: Expecting value: line 1 column 1 (char 0)
Traceback (most recent call last):
  File "/usr/src/homeassistant/homeassistant/helpers/update_coordinator.py", line 187, in _async_refresh
    self.data = await self._async_update_data()
  File "/usr/src/homeassistant/homeassistant/components/accuweather/__init__.py", line 99, in _async_update_data
    current = await self.accuweather.async_get_current_conditions()
  File "/usr/local/lib/python3.9/site-packages/accuweather/__init__.py", line 176, in async_get_current_conditions
    data = await self._async_get_data(url)
  File "/usr/local/lib/python3.9/site-packages/accuweather/__init__.py", line 141, in _async_get_data
    error_text = json.loads(await resp.text())
  File "/usr/local/lib/python3.9/json/__init__.py", line 346, in loads
    return _default_decoder.decode(s)
  File "/usr/local/lib/python3.9/json/decoder.py", line 337, in decode
    obj, end = self.raw_decode(s, idx=_w(s, 0).end())
  File "/usr/local/lib/python3.9/json/decoder.py", line 355, in raw_decode
    raise JSONDecodeError("Expecting value", s, err.value) from None
json.decoder.JSONDecodeError: Expecting value: line 1 column 1 (char 0)
2022-01-12 19:10:23 WARNING (MainThread) [custom_components.mail_and_packages.camera] Could not read camera Mail USPS Camera image from file: /config/custom_components/mail_and_packages/images/bf5d8ede-eb8d-4e3a-9184-6a4ed2af9f2d.gif
2022-01-12 22:14:24 WARNING (MainThread) [custom_components.mail_and_packages.camera] Could not read camera Mail USPS Camera image from file: /config/custom_components/mail_and_packages/images/bf5d8ede-eb8d-4e3a-9184-6a4ed2af9f2d.gif
2022-01-13 02:03:35 ERROR (MainThread) [aiohttp.server] Error handling request
Traceback (most recent call last):
  File "/usr/local/lib/python3.9/site-packages/aiohttp/web_protocol.py", line 334, in data_received
    messages, upgraded, tail = self._request_parser.feed_data(data)
  File "aiohttp/_http_parser.pyx", line 551, in aiohttp._http_parser.HttpParser.feed_data
aiohttp.http_exceptions.BadStatusLine: 400, message="Bad status line 'Invalid method encountered'"
2022-01-13 02:03:40 ERROR (MainThread) [aiohttp.server] Error handling request
Traceback (most recent call last):
  File "/usr/local/lib/python3.9/site-packages/aiohttp/web_protocol.py", line 334, in data_received
    messages, upgraded, tail = self._request_parser.feed_data(data)
  File "aiohttp/_http_parser.pyx", line 551, in aiohttp._http_parser.HttpParser.feed_data
aiohttp.http_exceptions.BadStatusLine: 400, message="Bad status line 'Invalid method encountered'"
2022-01-13 02:03:44 ERROR (MainThread) [aiohttp.server] Error handling request
Traceback (most recent call last):
  File "/usr/local/lib/python3.9/site-packages/aiohttp/web_protocol.py", line 334, in data_received
    messages, upgraded, tail = self._request_parser.feed_data(data)
  File "aiohttp/_http_parser.pyx", line 551, in aiohttp._http_parser.HttpParser.feed_data
aiohttp.http_exceptions.BadStatusLine: 400, message="Bad status line 'Invalid method encountered'"
2022-01-13 03:57:19 WARNING (MainThread) [homeassistant.helpers.template] Template variable warning: 'value3' is undefined when rendering '{{ value1 }} {{ value2 }} {{ value3 }}'
2022-01-13 03:57:19 WARNING (MainThread) [homeassistant.helpers.template] Template variable warning: 'target_id' is undefined when rendering '{{ target_id }}'
2022-01-13 03:57:19 WARNING (MainThread) [homeassistant.helpers.template] Template variable warning: 'content_type' is undefined when rendering '{{ content_type }}'
2022-01-13 03:57:19 WARNING (MainThread) [homeassistant.helpers.template] Template variable warning: 'channel_id' is undefined when rendering '{{ channel_id }}'
2022-01-13 03:57:19 WARNING (MainThread) [homeassistant.helpers.template] Template variable warning: 'importance_id' is undefined when rendering '{{ importance_id }}'
2022-01-13 04:31:17 ERROR (SyncWorker_0) [homeassistant.components.life360.device_tracker] get_circles: CommError: HTTPSConnectionPool(host='api.life360.com', port=443): Max retries exceeded with url: /v3/circles.json (Caused by NewConnectionError('<urllib3.connection.HTTPSConnection object at 0x7fb92d996760>: Failed to establish a new connection: [Errno -3] Try again'))
2022-01-13 04:31:20 ERROR (MainThread) [homeassistant.components.uptimerobot] Error fetching uptimerobot data: Request timeout for 'https://api.uptimerobot.com/v2/getMonitors'
2022-01-13 04:39:17 ERROR (SyncWorker_7) [homeassistant.components.life360.device_tracker] get_circles: CommError: HTTPSConnectionPool(host='api.life360.com', port=443): Max retries exceeded with url: /v3/circles.json (Caused by NewConnectionError('<urllib3.connection.HTTPSConnection object at 0x7fb92d9cc730>: Failed to establish a new connection: [Errno -3] Try again'))
2022-01-13 04:39:20 ERROR (MainThread) [homeassistant.components.uptimerobot] Error fetching uptimerobot data: Request timeout for 'https://api.uptimerobot.com/v2/getMonitors'
2022-01-13 05:30:00 ERROR (MainThread) [custom_components.auto_backup] Error during backup. Timeout on /backups/new/full request. There may be a backup already in progress.
2022-01-13 06:30:00 WARNING (MainThread) [homeassistant.helpers.service] Unable to find referenced entities switch.nodeid_21_switch
2022-01-13 06:30:01 WARNING (MainThread) [homeassistant.helpers.service] Unable to find referenced entities switch.nodeid_18_switch
2022-01-13 06:30:01 WARNING (MainThread) [homeassistant.helpers.service] Unable to find referenced entities switch.nodeid_19_switch
2022-01-13 06:30:01 WARNING (MainThread) [homeassistant.helpers.service] Unable to find referenced entities switch.nodeid_20_switch
2022-01-13 06:30:01 WARNING (MainThread) [homeassistant.helpers.service] Unable to find referenced entities switch.nodeid_20_switch
2022-01-13 06:30:03 WARNING (MainThread) [homeassistant.helpers.service] Unable to find referenced entities light.balcony_chandelier, light.kitchen_light_2, light.livingroom_receptacle_on_off, light.shelly_shbduo_1_d0cd10, light.shelly_shbduo_1_d1225f, switch.cabinet_lights_relay_2, switch.sink_light_relay_2
2022-01-13 07:36:35 WARNING (MainThread) [custom_components.mail_and_packages.camera] Could not read camera Mail USPS Camera image from file: /config/custom_components/mail_and_packages/images/3f9c8cc8-a5d1-4cb2-a3ff-302bf4267094.gif
2022-01-13 09:29:36 WARNING (MainThread) [custom_components.mail_and_packages.camera] Could not read camera Mail USPS Camera image from file: /config/custom_components/mail_and_packages/images/3f9c8cc8-a5d1-4cb2-a3ff-302bf4267094.gif
2022-01-13 09:50:02 WARNING (MainThread) [homeassistant.helpers.template] Template variable warning: 'value3' is undefined when rendering '{{ value1 }} {{ value2 }} {{ value3 }}'
2022-01-13 09:50:02 WARNING (MainThread) [homeassistant.helpers.template] Template variable warning: 'target_id' is undefined when rendering '{{ target_id }}'
2022-01-13 09:50:02 WARNING (MainThread) [homeassistant.helpers.template] Template variable warning: 'content_type' is undefined when rendering '{{ content_type }}'
2022-01-13 09:50:02 WARNING (MainThread) [homeassistant.helpers.template] Template variable warning: 'channel_id' is undefined when rendering '{{ channel_id }}'
2022-01-13 09:50:02 WARNING (MainThread) [homeassistant.helpers.template] Template variable warning: 'importance_id' is undefined when rendering '{{ importance_id }}'
2022-01-13 10:39:30 ERROR (MainThread) [homeassistant] Error doing job: Task exception was never retrieved
Traceback (most recent call last):
  File "/usr/local/lib/python3.9/site-packages/zigpy/device.py", line 265, in request
    result, msg = await self._application.request(
  File "/usr/local/lib/python3.9/site-packages/zigpy_znp/zigbee/application.py", line 453, in request
    return await self._send_request(
  File "/usr/local/lib/python3.9/site-packages/zigpy_znp/zigbee/application.py", line 1610, in _send_request
    raise DeliveryError(
zigpy.exceptions.DeliveryError: Request failed after 5 attempts: <Status.APS_NO_ACK: 183>
2022-01-13 11:12:08 WARNING (MainThread) [custom_components.mail_and_packages.camera] Could not read camera Mail USPS Camera image from file: /config/custom_components/mail_and_packages/images/3f9c8cc8-a5d1-4cb2-a3ff-302bf4267094.gif
2022-01-13 11:55:11 WARNING (MainThread) [homeassistant.helpers.service] Unable to find referenced entities switch.ge_enbrighten_z_wave_plus_smart_switch
2022-01-13 12:00:08 ERROR (MainThread) [aiohttp.server] Error handling request
Traceback (most recent call last):
  File "/usr/local/lib/python3.9/site-packages/aiohttp/web_protocol.py", line 334, in data_received
    messages, upgraded, tail = self._request_parser.feed_data(data)
  File "aiohttp/_http_parser.pyx", line 551, in aiohttp._http_parser.HttpParser.feed_data
aiohttp.http_exceptions.BadStatusLine: 400, message="Bad status line 'Invalid method encountered'"
2022-01-13 12:00:08 ERROR (MainThread) [aiohttp.server] Error handling request
Traceback (most recent call last):
  File "/usr/local/lib/python3.9/site-packages/aiohttp/web_protocol.py", line 334, in data_received
    messages, upgraded, tail = self._request_parser.feed_data(data)
  File "aiohttp/_http_parser.pyx", line 551, in aiohttp._http_parser.HttpParser.feed_data
aiohttp.http_exceptions.BadStatusLine: 400, message="Bad status line 'Invalid method encountered'"
2022-01-13 12:00:11 WARNING (MainThread) [homeassistant.helpers.service] Unable to find referenced entities switch.ge_enbrighten_z_wave_plus_smart_switch
2022-01-13 12:34:10 WARNING (MainThread) [custom_components.mail_and_packages.camera] Could not read camera Mail USPS Camera image from file: /config/custom_components/mail_and_packages/images/3f9c8cc8-a5d1-4cb2-a3ff-302bf4267094.gif
2022-01-13 15:57:20 WARNING (MainThread) [homeassistant.helpers.template] Template variable warning: 'value3' is undefined when rendering '{{ value1 }} {{ value2 }} {{ value3 }}'
2022-01-13 15:57:20 WARNING (MainThread) [homeassistant.helpers.template] Template variable warning: 'target_id' is undefined when rendering '{{ target_id }}'
2022-01-13 15:57:20 WARNING (MainThread) [homeassistant.helpers.template] Template variable warning: 'content_type' is undefined when rendering '{{ content_type }}'
2022-01-13 15:57:20 WARNING (MainThread) [homeassistant.helpers.template] Template variable warning: 'channel_id' is undefined when rendering '{{ channel_id }}'
2022-01-13 15:57:20 WARNING (MainThread) [homeassistant.helpers.template] Template variable warning: 'importance_id' is undefined when rendering '{{ importance_id }}'
2022-01-13 16:25:11 WARNING (MainThread) [custom_components.mail_and_packages.camera] Could not read camera Mail USPS Camera image from file: /config/custom_components/mail_and_packages/images/3f9c8cc8-a5d1-4cb2-a3ff-302bf4267094.gif
2022-01-13 17:16:41 WARNING (MainThread) [custom_components.mail_and_packages.camera] Could not read camera Mail USPS Camera image from file: /config/custom_components/mail_and_packages/images/3f9c8cc8-a5d1-4cb2-a3ff-302bf4267094.gif
2022-01-13 17:37:11 WARNING (MainThread) [custom_components.mail_and_packages.camera] Could not read camera Mail USPS Camera image from file: /config/custom_components/mail_and_packages/images/3f9c8cc8-a5d1-4cb2-a3ff-302bf4267094.gif
2022-01-13 17:57:12 ERROR (MainThread) [homeassistant.components.uptimerobot] Error fetching uptimerobot data: Request for 'https://api.uptimerobot.com/v2/getMonitors' failed with status code '502'
2022-01-13 18:12:52 WARNING (MainThread) [homeassistant.helpers.service] Unable to find referenced entities switch.ge_enbrighten_z_wave_plus_smart_switch
2022-01-13 18:17:52 WARNING (MainThread) [homeassistant.helpers.service] Unable to find referenced entities switch.ge_enbrighten_z_wave_plus_smart_switch
2022-01-13 19:31:19 ERROR (MainThread) [homeassistant.components.hassio.handler] Timeout on /homeassistant/restart request
