2021-11-06 22:24:40 WARNING (SyncWorker_1) [homeassistant.loader] We found a custom integration average which has not been tested by Home Assistant. This component might cause stability problems, be sure to disable it if you experience issues with Home Assistant
2021-11-06 22:24:40 WARNING (SyncWorker_1) [homeassistant.loader] We found a custom integration powercalc which has not been tested by Home Assistant. This component might cause stability problems, be sure to disable it if you experience issues with Home Assistant
2021-11-06 22:24:40 WARNING (SyncWorker_0) [homeassistant.loader] We found a custom integration nodered which has not been tested by Home Assistant. This component might cause stability problems, be sure to disable it if you experience issues with Home Assistant
2021-11-06 22:24:40 WARNING (SyncWorker_1) [homeassistant.loader] We found a custom integration weatherbit which has not been tested by Home Assistant. This component might cause stability problems, be sure to disable it if you experience issues with Home Assistant
2021-11-06 22:24:40 WARNING (SyncWorker_3) [homeassistant.loader] We found a custom integration hpprinter which has not been tested by Home Assistant. This component might cause stability problems, be sure to disable it if you experience issues with Home Assistant
2021-11-06 22:24:40 WARNING (SyncWorker_2) [homeassistant.loader] We found a custom integration lovelace_gen which has not been tested by Home Assistant. This component might cause stability problems, be sure to disable it if you experience issues with Home Assistant
2021-11-06 22:24:40 WARNING (SyncWorker_4) [homeassistant.loader] We found a custom integration hacs which has not been tested by Home Assistant. This component might cause stability problems, be sure to disable it if you experience issues with Home Assistant
2021-11-06 22:24:40 WARNING (SyncWorker_0) [homeassistant.loader] We found a custom integration myenergi which has not been tested by Home Assistant. This component might cause stability problems, be sure to disable it if you experience issues with Home Assistant
2021-11-06 22:24:40 WARNING (SyncWorker_3) [homeassistant.loader] We found a custom integration media_player_template which has not been tested by Home Assistant. This component might cause stability problems, be sure to disable it if you experience issues with Home Assistant
2021-11-06 22:24:40 WARNING (SyncWorker_1) [homeassistant.loader] We found a custom integration alexa_media which has not been tested by Home Assistant. This component might cause stability problems, be sure to disable it if you experience issues with Home Assistant
2021-11-06 22:24:40 WARNING (SyncWorker_4) [homeassistant.loader] We found a custom integration myq which has not been tested by Home Assistant. This component might cause stability problems, be sure to disable it if you experience issues with Home Assistant
2021-11-06 22:24:40 WARNING (SyncWorker_2) [homeassistant.loader] We found a custom integration mail_and_packages which has not been tested by Home Assistant. This component might cause stability problems, be sure to disable it if you experience issues with Home Assistant
2021-11-06 22:24:40 WARNING (SyncWorker_0) [homeassistant.loader] We found a custom integration garbage_collection which has not been tested by Home Assistant. This component might cause stability problems, be sure to disable it if you experience issues with Home Assistant
2021-11-06 22:24:40 WARNING (SyncWorker_5) [homeassistant.loader] We found a custom integration alarmo which has not been tested by Home Assistant. This component might cause stability problems, be sure to disable it if you experience issues with Home Assistant
2021-11-06 22:24:40 WARNING (SyncWorker_2) [homeassistant.loader] We found a custom integration pirateweather which has not been tested by Home Assistant. This component might cause stability problems, be sure to disable it if you experience issues with Home Assistant
2021-11-06 22:24:40 WARNING (SyncWorker_3) [homeassistant.loader] We found a custom integration auto_backup which has not been tested by Home Assistant. This component might cause stability problems, be sure to disable it if you experience issues with Home Assistant
2021-11-06 22:24:53 ERROR (MainThread) [homeassistant.components.websocket_api.http.connection] [139737914049776] Received invalid command: energy/info
2021-11-06 22:24:53 ERROR (MainThread) [homeassistant.components.websocket_api.http.connection] [139737914049776] Received invalid command: energy/info
2021-11-06 22:24:53 WARNING (MainThread) [homeassistant.helpers.template] Template variable warning: 'None' has no attribute 'state' when rendering '<ha-icon icon="mdi:home-assistant"></ha-icon>&nbsp;**Add-on update:** &nbsp;&nbsp; {{ states.sensor.supervisor_updates.state }}

> {% for addon in states.sensor.supervisor_updates.attributes.addons %}
> {{ addon.name }}&nbsp; {{ addon.version }} -> {{ addon.version_latest }}
> {% endfor %}

<ha-icon icon="hacs:hacs"></ha-icon>&nbsp;**HACS updates:** &nbsp;&nbsp; {{ states.sensor.hacs.state }}

> {% for repo in states.sensor.hacs.attributes.repositories %}
>  **{{ repo.display_name }}** _{{ repo["installed_version"] }}_ -> _{{repo["available_version"] }}_
> {% endfor %}'
2021-11-06 22:24:53 ERROR (MainThread) [homeassistant.helpers.template] Template variable error: 'None' has no attribute 'attributes' when rendering '<ha-icon icon="mdi:home-assistant"></ha-icon>&nbsp;**Add-on update:** &nbsp;&nbsp; {{ states.sensor.supervisor_updates.state }}

> {% for addon in states.sensor.supervisor_updates.attributes.addons %}
> {{ addon.name }}&nbsp; {{ addon.version }} -> {{ addon.version_latest }}
> {% endfor %}

<ha-icon icon="hacs:hacs"></ha-icon>&nbsp;**HACS updates:** &nbsp;&nbsp; {{ states.sensor.hacs.state }}

> {% for repo in states.sensor.hacs.attributes.repositories %}
>  **{{ repo.display_name }}** _{{ repo["installed_version"] }}_ -> _{{repo["available_version"] }}_
> {% endfor %}'
2021-11-06 22:24:53 WARNING (MainThread) [homeassistant.helpers.template] Template variable warning: 'None' has no attribute 'state' when rendering '<ha-icon icon="mdi:home-assistant"></ha-icon>&nbsp;**Add-on update:** &nbsp;&nbsp; {{ states.sensor.supervisor_updates.state }}

> {% for addon in states.sensor.supervisor_updates.attributes.addons %}
> {{ addon.name }}&nbsp; {{ addon.version }} -> {{ addon.version_latest }}
> {% endfor %}

<ha-icon icon="hacs:hacs"></ha-icon>&nbsp;**HACS updates:** &nbsp;&nbsp; {{ states.sensor.hacs.state }}

> {% for repo in states.sensor.hacs.attributes.repositories %}
>  **{{ repo.display_name }}** _{{ repo["installed_version"] }}_ -> _{{repo["available_version"] }}_
> {% endfor %}'
2021-11-06 22:24:53 ERROR (MainThread) [homeassistant.helpers.template] Template variable error: 'None' has no attribute 'attributes' when rendering '<ha-icon icon="mdi:home-assistant"></ha-icon>&nbsp;**Add-on update:** &nbsp;&nbsp; {{ states.sensor.supervisor_updates.state }}

> {% for addon in states.sensor.supervisor_updates.attributes.addons %}
> {{ addon.name }}&nbsp; {{ addon.version }} -> {{ addon.version_latest }}
> {% endfor %}

<ha-icon icon="hacs:hacs"></ha-icon>&nbsp;**HACS updates:** &nbsp;&nbsp; {{ states.sensor.hacs.state }}

> {% for repo in states.sensor.hacs.attributes.repositories %}
>  **{{ repo.display_name }}** _{{ repo["installed_version"] }}_ -> _{{repo["available_version"] }}_
> {% endfor %}'
2021-11-06 22:24:53 WARNING (MainThread) [homeassistant.helpers.template] Template variable warning: 'None' has no attribute 'state' when rendering '<ha-icon icon="mdi:home-assistant"></ha-icon>&nbsp;**Add-on update:** &nbsp;&nbsp; {{ states.sensor.supervisor_updates.state }}

> {% for addon in states.sensor.supervisor_updates.attributes.addons %}
> {{ addon.name }}&nbsp; {{ addon.version }} -> {{ addon.version_latest }}
> {% endfor %}

<ha-icon icon="hacs:hacs"></ha-icon>&nbsp;**HACS updates:** &nbsp;&nbsp; {{ states.sensor.hacs.state }}

> {% for repo in states.sensor.hacs.attributes.repositories %}
>  **{{ repo.display_name }}** _{{ repo["installed_version"] }}_ -> _{{repo["available_version"] }}_
> {% endfor %}'
2021-11-06 22:24:53 ERROR (MainThread) [homeassistant.helpers.template] Template variable error: 'None' has no attribute 'attributes' when rendering '<ha-icon icon="mdi:home-assistant"></ha-icon>&nbsp;**Add-on update:** &nbsp;&nbsp; {{ states.sensor.supervisor_updates.state }}

> {% for addon in states.sensor.supervisor_updates.attributes.addons %}
> {{ addon.name }}&nbsp; {{ addon.version }} -> {{ addon.version_latest }}
> {% endfor %}

<ha-icon icon="hacs:hacs"></ha-icon>&nbsp;**HACS updates:** &nbsp;&nbsp; {{ states.sensor.hacs.state }}

> {% for repo in states.sensor.hacs.attributes.repositories %}
>  **{{ repo.display_name }}** _{{ repo["installed_version"] }}_ -> _{{repo["available_version"] }}_
> {% endfor %}'
2021-11-06 22:24:53 WARNING (MainThread) [homeassistant.helpers.template] Template variable warning: 'None' has no attribute 'state' when rendering '<ha-icon icon="mdi:home-assistant"></ha-icon>&nbsp;**Add-on update:** &nbsp;&nbsp; {{ states.sensor.supervisor_updates.state }}

> {% for addon in states.sensor.supervisor_updates.attributes.addons %}
> {{ addon.name }}&nbsp; {{ addon.version }} -> {{ addon.version_latest }}
> {% endfor %}

<ha-icon icon="hacs:hacs"></ha-icon>&nbsp;**HACS updates:** &nbsp;&nbsp; {{ states.sensor.hacs.state }}

> {% for repo in states.sensor.hacs.attributes.repositories %}
>  **{{ repo.display_name }}** _{{ repo["installed_version"] }}_ -> _{{repo["available_version"] }}_
> {% endfor %}'
2021-11-06 22:24:53 ERROR (MainThread) [homeassistant.helpers.template] Template variable error: 'None' has no attribute 'attributes' when rendering '<ha-icon icon="mdi:home-assistant"></ha-icon>&nbsp;**Add-on update:** &nbsp;&nbsp; {{ states.sensor.supervisor_updates.state }}

> {% for addon in states.sensor.supervisor_updates.attributes.addons %}
> {{ addon.name }}&nbsp; {{ addon.version }} -> {{ addon.version_latest }}
> {% endfor %}

<ha-icon icon="hacs:hacs"></ha-icon>&nbsp;**HACS updates:** &nbsp;&nbsp; {{ states.sensor.hacs.state }}

> {% for repo in states.sensor.hacs.attributes.repositories %}
>  **{{ repo.display_name }}** _{{ repo["installed_version"] }}_ -> _{{repo["available_version"] }}_
> {% endfor %}'
2021-11-06 22:24:53 WARNING (MainThread) [homeassistant.helpers.template] Template variable warning: 'None' has no attribute 'state' when rendering '<ha-icon icon="mdi:home-assistant"></ha-icon>&nbsp;**Add-on update:** &nbsp;&nbsp; {{ states.sensor.supervisor_updates.state }}

> {% for addon in states.sensor.supervisor_updates.attributes.addons %}
> {{ addon.name }}&nbsp; {{ addon.version }} -> {{ addon.version_latest }}
> {% endfor %}

<ha-icon icon="hacs:hacs"></ha-icon>&nbsp;**HACS updates:** &nbsp;&nbsp; {{ states.sensor.hacs.state }}

> {% for repo in states.sensor.hacs.attributes.repositories %}
>  **{{ repo.display_name }}** _{{ repo["installed_version"] }}_ -> _{{repo["available_version"] }}_
> {% endfor %}'
2021-11-06 22:24:53 ERROR (MainThread) [homeassistant.helpers.template] Template variable error: 'None' has no attribute 'attributes' when rendering '<ha-icon icon="mdi:home-assistant"></ha-icon>&nbsp;**Add-on update:** &nbsp;&nbsp; {{ states.sensor.supervisor_updates.state }}

> {% for addon in states.sensor.supervisor_updates.attributes.addons %}
> {{ addon.name }}&nbsp; {{ addon.version }} -> {{ addon.version_latest }}
> {% endfor %}

<ha-icon icon="hacs:hacs"></ha-icon>&nbsp;**HACS updates:** &nbsp;&nbsp; {{ states.sensor.hacs.state }}

> {% for repo in states.sensor.hacs.attributes.repositories %}
>  **{{ repo.display_name }}** _{{ repo["installed_version"] }}_ -> _{{repo["available_version"] }}_
> {% endfor %}'
2021-11-06 22:24:53 WARNING (MainThread) [homeassistant.helpers.template] Template variable warning: 'None' has no attribute 'state' when rendering '<ha-icon icon="mdi:home-assistant"></ha-icon>&nbsp;**Add-on update:** &nbsp;&nbsp; {{ states.sensor.supervisor_updates.state }}

> {% for addon in states.sensor.supervisor_updates.attributes.addons %}
> {{ addon.name }}&nbsp; {{ addon.version }} -> {{ addon.version_latest }}
> {% endfor %}

<ha-icon icon="hacs:hacs"></ha-icon>&nbsp;**HACS updates:** &nbsp;&nbsp; {{ states.sensor.hacs.state }}

> {% for repo in states.sensor.hacs.attributes.repositories %}
>  **{{ repo.display_name }}** _{{ repo["installed_version"] }}_ -> _{{repo["available_version"] }}_
> {% endfor %}'
2021-11-06 22:24:53 ERROR (MainThread) [homeassistant.helpers.template] Template variable error: 'None' has no attribute 'attributes' when rendering '<ha-icon icon="mdi:home-assistant"></ha-icon>&nbsp;**Add-on update:** &nbsp;&nbsp; {{ states.sensor.supervisor_updates.state }}

> {% for addon in states.sensor.supervisor_updates.attributes.addons %}
> {{ addon.name }}&nbsp; {{ addon.version }} -> {{ addon.version_latest }}
> {% endfor %}

<ha-icon icon="hacs:hacs"></ha-icon>&nbsp;**HACS updates:** &nbsp;&nbsp; {{ states.sensor.hacs.state }}

> {% for repo in states.sensor.hacs.attributes.repositories %}
>  **{{ repo.display_name }}** _{{ repo["installed_version"] }}_ -> _{{repo["available_version"] }}_
> {% endfor %}'
2021-11-06 22:24:53 WARNING (MainThread) [homeassistant.helpers.template] Template variable warning: 'None' has no attribute 'state' when rendering '<ha-icon icon="mdi:home-assistant"></ha-icon>&nbsp;**Add-on update:** &nbsp;&nbsp; {{ states.sensor.supervisor_updates.state }}

> {% for addon in states.sensor.supervisor_updates.attributes.addons %}
> {{ addon.name }}&nbsp; {{ addon.version }} -> {{ addon.version_latest }}
> {% endfor %}

<ha-icon icon="hacs:hacs"></ha-icon>&nbsp;**HACS updates:** &nbsp;&nbsp; {{ states.sensor.hacs.state }}

> {% for repo in states.sensor.hacs.attributes.repositories %}
>  **{{ repo.display_name }}** _{{ repo["installed_version"] }}_ -> _{{repo["available_version"] }}_
> {% endfor %}'
2021-11-06 22:24:53 ERROR (MainThread) [homeassistant.helpers.template] Template variable error: 'None' has no attribute 'attributes' when rendering '<ha-icon icon="mdi:home-assistant"></ha-icon>&nbsp;**Add-on update:** &nbsp;&nbsp; {{ states.sensor.supervisor_updates.state }}

> {% for addon in states.sensor.supervisor_updates.attributes.addons %}
> {{ addon.name }}&nbsp; {{ addon.version }} -> {{ addon.version_latest }}
> {% endfor %}

<ha-icon icon="hacs:hacs"></ha-icon>&nbsp;**HACS updates:** &nbsp;&nbsp; {{ states.sensor.hacs.state }}

> {% for repo in states.sensor.hacs.attributes.repositories %}
>  **{{ repo.display_name }}** _{{ repo["installed_version"] }}_ -> _{{repo["available_version"] }}_
> {% endfor %}'
2021-11-06 22:25:02 WARNING (SyncWorker_9) [homeassistant.components.local_file.camera] Could not read camera mail_usps image from file: /custom_components/mail_and_packages/mail_none.gif
2021-11-06 22:25:03 WARNING (MainThread) [alexapy.alexalogin] No access token found; falling back to credential login instead of oauth.
2021-11-06 22:25:08 WARNING (MainThread) [homeassistant.setup] Setup of zone is taking over 10 seconds.
2021-11-06 22:25:09 WARNING (MainThread) [homeassistant.config_entries] Config entry 'Home' for accuweather integration not ready yet; Retrying in background
2021-11-06 22:25:10 WARNING (MainThread) [homeassistant.setup] Setup of webostv is taking over 10 seconds.
2021-11-06 22:25:18 WARNING (MainThread) [aioesphomeapi.reconnect_logic] Can't connect to ESPHome API for 192.168.1.115 @ 192.168.1.115: Error connecting to ('192.168.1.115', 6053): [Errno 113] Connect call failed ('192.168.1.115', 6053)
2021-11-06 22:25:37 WARNING (Thread-29) [matplotlib.font_manager] Matplotlib is building the font cache; this may take a moment.
2021-11-06 22:25:41 ERROR (MainThread) [homeassistant.config_entries] Error unloading entry 192.168.1.24 for binary_sensor
Traceback (most recent call last):
  File "/usr/src/homeassistant/homeassistant/config_entries.py", line 443, in async_unload
    result = await component.async_unload_entry(hass, self)  # type: ignore
  File "/usr/src/homeassistant/homeassistant/components/binary_sensor/__init__.py", line 162, in async_unload_entry
    return await component.async_unload_entry(entry)
  File "/usr/src/homeassistant/homeassistant/helpers/entity_component.py", line 181, in async_unload_entry
    raise ValueError("Config entry was never loaded!")
ValueError: Config entry was never loaded!
2021-11-06 22:25:41 ERROR (MainThread) [homeassistant.config_entries] Error unloading entry 192.168.1.24 for camera
Traceback (most recent call last):
  File "/usr/src/homeassistant/homeassistant/config_entries.py", line 443, in async_unload
    result = await component.async_unload_entry(hass, self)  # type: ignore
  File "/usr/src/homeassistant/homeassistant/components/camera/__init__.py", line 368, in async_unload_entry
    return await component.async_unload_entry(entry)
  File "/usr/src/homeassistant/homeassistant/helpers/entity_component.py", line 181, in async_unload_entry
    raise ValueError("Config entry was never loaded!")
ValueError: Config entry was never loaded!
2021-11-06 22:25:41 ERROR (MainThread) [homeassistant.config_entries] Error unloading entry 192.168.1.24 for sensor
Traceback (most recent call last):
  File "/usr/src/homeassistant/homeassistant/config_entries.py", line 443, in async_unload
    result = await component.async_unload_entry(hass, self)  # type: ignore
  File "/usr/src/homeassistant/homeassistant/components/sensor/__init__.py", line 134, in async_unload_entry
    return await component.async_unload_entry(entry)
  File "/usr/src/homeassistant/homeassistant/helpers/entity_component.py", line 181, in async_unload_entry
    raise ValueError("Config entry was never loaded!")
ValueError: Config entry was never loaded!
2021-11-06 22:25:41 ERROR (MainThread) [homeassistant.config_entries] Error unloading entry 192.168.1.24 for switch
Traceback (most recent call last):
  File "/usr/src/homeassistant/homeassistant/config_entries.py", line 443, in async_unload
    result = await component.async_unload_entry(hass, self)  # type: ignore
  File "/usr/src/homeassistant/homeassistant/components/switch/__init__.py", line 85, in async_unload_entry
    return await component.async_unload_entry(entry)
  File "/usr/src/homeassistant/homeassistant/helpers/entity_component.py", line 181, in async_unload_entry
    raise ValueError("Config entry was never loaded!")
ValueError: Config entry was never loaded!
2021-11-06 22:30:11 WARNING (Recorder) [homeassistant.components.sensor.recorder] sensor.desktop_daily_energy has unknown unit W
2021-11-06 22:30:11 WARNING (Recorder) [homeassistant.components.sensor.recorder] sensor.ewva_daily_energy has unknown unit W
2021-11-06 22:30:11 WARNING (Recorder) [homeassistant.components.sensor.recorder] sensor.sink_light_daily_energy has unknown unit W
2021-11-06 22:30:11 WARNING (Recorder) [homeassistant.components.sensor.recorder] sensor.cabinet_lights_daily_energy has unknown unit W
2021-11-06 22:30:11 WARNING (Recorder) [homeassistant.components.sensor.recorder] sensor.master_bath_light_daily_energy has unknown unit W
2021-11-06 22:30:11 WARNING (Recorder) [homeassistant.components.sensor.recorder] sensor.master_bath_fan_daily_energy has unknown unit W
2021-11-06 22:30:11 WARNING (Recorder) [homeassistant.components.sensor.recorder] sensor.counter_lights_daily_energy has unknown unit kW
2021-11-06 22:30:11 WARNING (Recorder) [homeassistant.components.sensor.recorder] sensor.tooster_daily_energy has unknown unit kW
2021-11-06 22:30:11 WARNING (Recorder) [homeassistant.components.sensor.recorder] sensor.pond_aerator_daily_energy has unknown unit kW
2021-11-06 22:46:21 WARNING (MainThread) [homeassistant.components.media_player] Updating dlna_dmr media_player took longer than the scheduled update interval 0:00:10
2021-11-06 22:46:21 WARNING (MainThread) [homeassistant.helpers.entity] Update of media_player.lgpc_ed_eds_desktop is taking over 10 seconds
2021-11-06 22:53:55 WARNING (MainThread) [aioesphomeapi.reconnect_logic] Can't connect to ESPHome API for spare-plug.local @ spare-plug.local: Error connecting to ('192.168.1.64', 6053): [Errno 113] Connect call failed ('192.168.1.64', 6053)
2021-11-06 22:54:53 WARNING (MainThread) [aioesphomeapi.reconnect_logic] Can't connect to ESPHome API for 192.168.1.131 @ 192.168.1.131: Error connecting to ('192.168.1.131', 6053): [Errno 113] Connect call failed ('192.168.1.131', 6053)
2021-11-06 22:54:55 WARNING (MainThread) [aioesphomeapi.reconnect_logic] Can't connect to ESPHome API for office-picture-lights.local @ office-picture-lights.local: Error connecting to ('192.168.1.120', 6053): [Errno 113] Connect call failed ('192.168.1.120', 6053)
2021-11-06 22:54:55 WARNING (MainThread) [aioesphomeapi.reconnect_logic] Can't connect to ESPHome API for cloths-dryer.local @ cloths-dryer.local: Error connecting to ('192.168.1.161', 6053): [Errno 113] Connect call failed ('192.168.1.161', 6053)
2021-11-06 22:54:55 WARNING (MainThread) [aioesphomeapi.reconnect_logic] Can't connect to ESPHome API for nook-light-shelly1.local @ nook-light-shelly1.local: Error connecting to ('192.168.1.104', 6053): [Errno 113] Connect call failed ('192.168.1.104', 6053)
2021-11-07 00:20:00 ERROR (MainThread) [custom_components.auto_backup] Error during backup. Timeout on /backups/new/partial request. There may be a backup already in progress.
2021-11-07 00:35:58 WARNING (MainThread) [homeassistant.helpers.entity] Updating state for sensor.cabinet_lights_daily_energy (<class 'homeassistant.components.esphome.sensor.EsphomeSensor'>) took 1.144 seconds. Please create a bug report at https://github.com/home-assistant/core/issues?q=is%3Aopen+is%3Aissue+label%3A%22integration%3A+esphome%22
2021-11-07 01:11:24 WARNING (MainThread) [aioesphomeapi.reconnect_logic] Can't connect to ESPHome API for 192.168.1.154 @ 192.168.1.154: Error connecting to ('192.168.1.154', 6053): [Errno 113] Connect call failed ('192.168.1.154', 6053)
2021-11-07 03:20:00 ERROR (MainThread) [custom_components.auto_backup] Error during backup. Timeout on /backups/new/partial request. There may be a backup already in progress.
2021-11-07 03:25:49 WARNING (MainThread) [zeroconf] Received invalid packet from ('::ffff:192.168.1.62', 5353) at offset 106 while unpacking b'\x00\x00\x84\x00\x00\x00\x00\x04\x00\x00\x00\x01\x00\x00\x0c\x00\x01\x00\x00\x01,\x00\x04\x02\x880\x00\x02\x880\x00\x00!\x80\x01\x00\x00\x01,\x00\x0b\xf3\x08\x80\xef\xf3\t\x03\x81rF\x00\x07MyQ-1EB\x05local\x00\x00\x01\x80\x01\x00\x00\x01,\x00\x04\xc0\xa8\x01>\x02\x880\x00\x00/\x80\x01\x00\x00\x01,\x00\x0b\x02\x880\x00\x00\x05\x00\x08\x00\x00@'
Traceback (most recent call last):
  File "/usr/local/lib/python3.9/site-packages/zeroconf/_protocol/incoming.py", line 111, in _parse_data
    parser_call()
  File "/usr/local/lib/python3.9/site-packages/zeroconf/_protocol/incoming.py", line 105, in _initial_parse
    self.read_others()
  File "/usr/local/lib/python3.9/site-packages/zeroconf/_protocol/incoming.py", line 185, in read_others
    domain = self.read_name()
  File "/usr/local/lib/python3.9/site-packages/zeroconf/_protocol/incoming.py", line 275, in read_name
    self.offset = self._decode_labels_at_offset(self.offset, labels, seen_pointers)
  File "/usr/local/lib/python3.9/site-packages/zeroconf/_protocol/incoming.py", line 315, in _decode_labels_at_offset
    raise IncomingDecodeError("Corrupt packet received while decoding name")
zeroconf._exceptions.IncomingDecodeError: Corrupt packet received while decoding name
2021-11-07 05:50:00 ERROR (MainThread) [custom_components.auto_backup] Error during backup. Timeout on /backups/new/full request. There may be a backup already in progress.
2021-11-07 06:00:00 ERROR (MainThread) [custom_components.auto_backup] Error during backup. Unknown error, see supervisor. There may be a backup already in progress.
2021-11-07 06:30:00 WARNING (MainThread) [homeassistant.helpers.service] Unable to find referenced entities switch.nodeid_21_switch
2021-11-07 06:30:00 WARNING (MainThread) [homeassistant.helpers.service] Unable to find referenced entities switch.nodeid_18_switch
2021-11-07 06:30:00 WARNING (MainThread) [homeassistant.helpers.service] Unable to find referenced entities switch.nodeid_19_switch
2021-11-07 06:30:00 WARNING (MainThread) [homeassistant.helpers.service] Unable to find referenced entities switch.nodeid_20_switch
2021-11-07 06:30:00 WARNING (MainThread) [homeassistant.helpers.service] Unable to find referenced entities switch.nodeid_20_switch
2021-11-07 06:30:00 WARNING (MainThread) [homeassistant.helpers.service] Unable to find referenced entities light.balcony_chandelier, light.kitchen_light_2, light.livingroom_receptacle_on_off, light.shelly_shbduo_1_d0cd10, light.shelly_shbduo_1_d1225f, switch.cabinet_lights_relay_2, switch.sink_light_relay_2
2021-11-07 06:46:45 WARNING (MainThread) [aioesphomeapi.reconnect_logic] Can't connect to ESPHome API for dish-washer.local @ dish-washer.local: Error resolving IP address: [Errno -2] Name does not resolve
2021-11-07 06:46:49 WARNING (MainThread) [aioesphomeapi.reconnect_logic] Can't connect to ESPHome API for kitchen-circuit-0.local @ kitchen-circuit-0.local: Error resolving IP address: [Errno -2] Name does not resolve
2021-11-07 07:19:32 WARNING (MainThread) [aioesphomeapi.reconnect_logic] Can't connect to ESPHome API for office-picture-lights.local @ office-picture-lights.local: Error resolving IP address: [Errno -2] Name does not resolve
2021-11-07 07:19:33 WARNING (MainThread) [aioesphomeapi.reconnect_logic] Can't connect to ESPHome API for dish-washer.local @ dish-washer.local: Error resolving IP address: [Errno -2] Name does not resolve
2021-11-07 07:19:50 WARNING (MainThread) [aioesphomeapi.reconnect_logic] Can't connect to ESPHome API for 192.168.1.121 @ 192.168.1.121: Hello timed out
2021-11-07 07:41:13 ERROR (MainThread) [homeassistant] Error doing job: Fatal error: protocol.data_received() call failed.
Traceback (most recent call last):
  File "/usr/local/lib/python3.9/asyncio/selector_events.py", line 870, in _read_ready__data_received
    self._protocol.data_received(data)
  File "/usr/local/lib/python3.9/site-packages/aiohomekit/controller/ip/connection.py", line 202, in data_received
    super().data_received(decrypted)
  File "/usr/local/lib/python3.9/site-packages/aiohomekit/controller/ip/connection.py", line 96, in data_received
    data = self.current_response.parse(data)
  File "/usr/local/lib/python3.9/site-packages/aiohomekit/http/response.py", line 86, in parse
    length = int(line, 16)
ValueError: invalid literal for int() with base 16: b'Gh\xfc\x17\xa9\xa7\r%\xee\x007w2]\x0f\xf9\xe4\x9f\xbb\x8c~\x03\x93\xf8\xd5\xa1\x0c\x9fP\x84LaBnf\xc7\xfa\xbbq\xbc\xfe=\x855\xa1\xbc\xba8\x91\x96\xca1\xc6\x17\xe7\x93\xf3\xe8*\xec1\xad\xbam\x8a5\x8d}
2021-11-07 07:41:24 ERROR (MainThread) [homeassistant] Error doing job: Fatal error: protocol.data_received() call failed.
Traceback (most recent call last):
  File "/usr/local/lib/python3.9/asyncio/selector_events.py", line 870, in _read_ready__data_received
    self._protocol.data_received(data)
  File "/usr/local/lib/python3.9/site-packages/aiohomekit/controller/ip/connection.py", line 202, in data_received
    super().data_received(decrypted)
  File "/usr/local/lib/python3.9/site-packages/aiohomekit/controller/ip/connection.py", line 96, in data_received
    data = self.current_response.parse(data)
  File "/usr/local/lib/python3.9/site-packages/aiohomekit/http/response.py", line 86, in parse
    length = int(line, 16)
ValueError: invalid literal for int() with base 16: b'm0\xcc\x83\xedw2\\\x83\xff\x00,\xd3\xf7i\xf9\x0eO\xe3V\x846}F(\xe40\xaf\xfaD\xb8\xff\x00W\x07\xcc\x7f\x1ct\xa8\x8c\x17\x97\x00y\x8c\xb61\xf4\xdb\x1f\xcf\'\xe7\xd0U\xe8c[x\x84q"\xc6\xbf\xdd\x8dp*6\xb
2021-11-07 07:44:04 ERROR (MainThread) [homeassistant] Error doing job: Fatal error: protocol.data_received() call failed.
Traceback (most recent call last):
  File "/usr/local/lib/python3.9/asyncio/selector_events.py", line 870, in _read_ready__data_received
    self._protocol.data_received(data)
  File "/usr/local/lib/python3.9/site-packages/aiohomekit/controller/ip/connection.py", line 202, in data_received
    super().data_received(decrypted)
  File "/usr/local/lib/python3.9/site-packages/aiohomekit/controller/ip/connection.py", line 96, in data_received
    data = self.current_response.parse(data)
  File "/usr/local/lib/python3.9/site-packages/aiohomekit/http/response.py", line 86, in parse
    length = int(line, 16)
ValueError: invalid literal for int() with base 16: b"SJt\xc7\x98\x7f\xa6\\\xbc\xfe\xb1'\xee\xe3\xfc\x87&\xa8A6\xa1\x04R\xf9JL\xf2\xff\x00\xcf(\x06\xf6\xfc{\n\x8d\xa2\xbc\xba\xfb\xe5l\x93\xa6\x13\xe6\x93\xf3\xe8*\xdc1\x0bh\xc4q\xa2\xa0\xc7H\xd7\x02\x98
2021-11-07 08:30:11 ERROR (MainThread) [homeassistant.components.speedtestdotnet] Error fetching speedtestdotnet data: Unable to connect to servers to test latency.
2021-11-07 09:20:00 ERROR (MainThread) [custom_components.auto_backup] Error during backup. Timeout on /backups/new/partial request. There may be a backup already in progress.
2021-11-07 09:58:03 WARNING (MainThread) [aioesphomeapi.reconnect_logic] Can't connect to ESPHome API for 192.168.1.121 @ 192.168.1.121: Timeout while connecting to ('192.168.1.121', 6053)
2021-11-07 11:09:38 WARNING (MainThread) [aioesphomeapi.reconnect_logic] Can't connect to ESPHome API for 192.168.1.121 @ 192.168.1.121: Timeout waiting for response for <class 'api_pb2.ConnectRequest'>
2021-11-07 11:12:58 ERROR (MainThread) [homeassistant.components.uptimerobot] Error fetching uptimerobot data: Request exception for 'https://api.uptimerobot.com/v2/getMonitors' with - [Errno 104] Connection reset by peer
2021-11-07 11:19:58 ERROR (MainThread) [homeassistant.components.uptimerobot] Error fetching uptimerobot data: Request exception for 'https://api.uptimerobot.com/v2/getMonitors' with - [Errno 104] Connection reset by peer
2021-11-07 11:25:44 ERROR (MainThread) [frontend.js.latest.202111030] :0:0 ResizeObserver loop completed with undelivered notifications.
2021-11-07 11:25:44 ERROR (MainThread) [frontend.js.latest.202111030] :0:0 ResizeObserver loop completed with undelivered notifications.
2021-11-07 11:25:53 ERROR (MainThread) [frontend.js.latest.202111030] :0:0 ResizeObserver loop completed with undelivered notifications.
2021-11-07 11:35:41 ERROR (MainThread) [homeassistant] Error doing job: Task exception was never retrieved
Traceback (most recent call last):
  File "/usr/src/homeassistant/homeassistant/components/hassio/__init__.py", line 555, in update_info_data
    await hass.data[ADDONS_COORDINATOR].async_refresh()
  File "/usr/src/homeassistant/homeassistant/helpers/update_coordinator.py", line 165, in async_refresh
    await self._async_refresh(log_failures=True)
  File "/usr/src/homeassistant/homeassistant/helpers/update_coordinator.py", line 265, in _async_refresh
    update_callback()
  File "/usr/src/homeassistant/homeassistant/helpers/update_coordinator.py", line 325, in _handle_coordinator_update
    self.async_write_ha_state()
  File "/usr/src/homeassistant/homeassistant/helpers/entity.py", line 486, in async_write_ha_state
    self._async_write_ha_state()
  File "/usr/src/homeassistant/homeassistant/helpers/entity.py", line 519, in _async_write_ha_state
    state = self._stringify_state()
  File "/usr/src/homeassistant/homeassistant/helpers/entity.py", line 490, in _stringify_state
    if not self.available:
  File "/usr/src/homeassistant/homeassistant/components/hassio/entity.py", line 37, in available
    in self.coordinator.data[DATA_KEY_ADDONS][self._addon_slug]
KeyError: 'addons'
2021-11-07 12:01:15 ERROR (MainThread) [homeassistant] Error doing job: Future exception was never retrieved
Traceback (most recent call last):
  File "/usr/local/lib/python3.9/site-packages/aioesphomeapi/_frame_helper.py", line 68, in write_packet
    await self._writer.drain()
  File "/usr/local/lib/python3.9/asyncio/streams.py", line 387, in drain
    await self._protocol._drain_helper()
  File "/usr/local/lib/python3.9/asyncio/streams.py", line 190, in _drain_helper
    raise ConnectionResetError('Connection lost')
ConnectionResetError: Connection lost

The above exception was the direct cause of the following exception:

Traceback (most recent call last):
  File "/usr/local/lib/python3.9/site-packages/aioesphomeapi/reconnect_logic.py", line 121, in _try_connect
    await self._cli.connect(on_stop=self._on_disconnect, login=True)
  File "/usr/local/lib/python3.9/site-packages/aioesphomeapi/client.py", line 173, in connect
    await self._connection.connect(login=login)
  File "/usr/local/lib/python3.9/site-packages/aioesphomeapi/connection.py", line 262, in connect
    await self._connect_hello()
  File "/usr/local/lib/python3.9/site-packages/aioesphomeapi/connection.py", line 189, in _connect_hello
    resp = await self.send_message_await_response(hello, HelloResponse)
  File "/usr/local/lib/python3.9/site-packages/aioesphomeapi/connection.py", line 411, in send_message_await_response
    res = await self.send_message_await_response_complex(
  File "/usr/local/lib/python3.9/site-packages/aioesphomeapi/connection.py", line 389, in send_message_await_response_complex
    await self.send_message(send_msg)
  File "/usr/local/lib/python3.9/site-packages/aioesphomeapi/connection.py", line 333, in send_message
    await self._frame_helper.write_packet(
  File "/usr/local/lib/python3.9/site-packages/aioesphomeapi/_frame_helper.py", line 70, in write_packet
    raise SocketAPIError(f"Error while writing data: {err}") from err
aioesphomeapi.core.SocketAPIError: Error while writing data: Connection lost
2021-11-07 12:20:01 ERROR (MainThread) [custom_components.auto_backup] Error during backup. Timeout on /backups/new/partial request. There may be a backup already in progress.
2021-11-07 12:34:23 ERROR (MainThread) [homeassistant.components.hassio.handler] Timeout on /homeassistant/restart request
2021-11-07 12:35:52 WARNING (MainThread) [homeassistant.core] Timed out waiting for shutdown stage 1 to complete, the shutdown will continue
2021-11-07 12:35:53 WARNING (Thread-1337) [homeassistant.util.executor] Thread[SyncWorker_11] is still running at shutdown: File "/usr/local/lib/python3.9/threading.py", line 930, in _bootstrap
    self._bootstrap_inner()
  File "/usr/local/lib/python3.9/threading.py", line 973, in _bootstrap_inner
    self.run()
  File "/usr/local/lib/python3.9/threading.py", line 910, in run
    self._target(*self._args, **self._kwargs)
  File "/usr/local/lib/python3.9/concurrent/futures/thread.py", line 77, in _worker
    work_item.run()
  File "/usr/local/lib/python3.9/concurrent/futures/thread.py", line 52, in run
    result = self.fn(*self.args, **self.kwargs)
  File "/usr/src/homeassistant/homeassistant/components/recorder/__init__.py", line 542, in shutdown
    self.join()
  File "/usr/local/lib/python3.9/threading.py", line 1053, in join
    self._wait_for_tstate_lock()
  File "/usr/local/lib/python3.9/threading.py", line 1069, in _wait_for_tstate_lock
    elif lock.acquire(block, timeout):
2021-11-07 12:35:54 WARNING (Thread-1337) [homeassistant.util.executor] Thread[SyncWorker_11] is still running at shutdown: File "/usr/local/lib/python3.9/threading.py", line 930, in _bootstrap
    self._bootstrap_inner()
  File "/usr/local/lib/python3.9/threading.py", line 973, in _bootstrap_inner
    self.run()
  File "/usr/local/lib/python3.9/threading.py", line 910, in run
    self._target(*self._args, **self._kwargs)
  File "/usr/local/lib/python3.9/concurrent/futures/thread.py", line 77, in _worker
    work_item.run()
  File "/usr/local/lib/python3.9/concurrent/futures/thread.py", line 52, in run
    result = self.fn(*self.args, **self.kwargs)
  File "/usr/src/homeassistant/homeassistant/components/recorder/__init__.py", line 542, in shutdown
    self.join()
  File "/usr/local/lib/python3.9/threading.py", line 1053, in join
    self._wait_for_tstate_lock()
  File "/usr/local/lib/python3.9/threading.py", line 1069, in _wait_for_tstate_lock
    elif lock.acquire(block, timeout):
2021-11-07 12:35:55 ERROR (MainThread) [homeassistant] Error doing job: Exception in callback async_track_point_in_utc_time.<locals>.run_action(<Job HassJobT...7f1737f4edc0>>) at /usr/src/homeassistant/homeassistant/helpers/event.py:1227
Traceback (most recent call last):
  File "/usr/local/lib/python3.9/asyncio/events.py", line 80, in _run
    self._context.run(self._callback, *self._args)
  File "/usr/src/homeassistant/homeassistant/helpers/event.py", line 1245, in run_action
    hass.async_run_hass_job(job, utc_point_in_time)
  File "/usr/src/homeassistant/homeassistant/core.py", line 433, in async_run_hass_job
    hassjob.target(*args)
  File "/usr/src/homeassistant/homeassistant/helpers/event.py", line 1305, in interval_listener
    hass.async_run_hass_job(job, now)
  File "/usr/src/homeassistant/homeassistant/core.py", line 436, in async_run_hass_job
    return self.async_add_hass_job(hassjob, *args)
  File "/usr/src/homeassistant/homeassistant/core.py", line 368, in async_add_hass_job
    task = self.loop.run_in_executor(  # type: ignore
  File "/usr/local/lib/python3.9/asyncio/base_events.py", line 814, in run_in_executor
    executor.submit(func, *args), loop=self)
  File "/usr/local/lib/python3.9/concurrent/futures/thread.py", line 161, in submit
    raise RuntimeError('cannot schedule new futures after shutdown')
RuntimeError: cannot schedule new futures after shutdown
2021-11-07 12:36:03 WARNING (MainThread) [homeassistant.util.executor] Thread[SyncWorker_11] is still running at shutdown: File "/usr/local/lib/python3.9/threading.py", line 930, in _bootstrap
    self._bootstrap_inner()
  File "/usr/local/lib/python3.9/threading.py", line 973, in _bootstrap_inner
    self.run()
  File "/usr/local/lib/python3.9/threading.py", line 910, in run
    self._target(*self._args, **self._kwargs)
  File "/usr/local/lib/python3.9/concurrent/futures/thread.py", line 77, in _worker
    work_item.run()
  File "/usr/local/lib/python3.9/concurrent/futures/thread.py", line 52, in run
    result = self.fn(*self.args, **self.kwargs)
  File "/usr/src/homeassistant/homeassistant/components/recorder/__init__.py", line 542, in shutdown
    self.join()
  File "/usr/local/lib/python3.9/threading.py", line 1053, in join
    self._wait_for_tstate_lock()
  File "/usr/local/lib/python3.9/threading.py", line 1069, in _wait_for_tstate_lock
    elif lock.acquire(block, timeout):
2021-11-07 12:36:04 WARNING (MainThread) [homeassistant.util.executor] Thread[SyncWorker_11] is still running at shutdown: File "/usr/local/lib/python3.9/threading.py", line 930, in _bootstrap
    self._bootstrap_inner()
  File "/usr/local/lib/python3.9/threading.py", line 973, in _bootstrap_inner
    self.run()
  File "/usr/local/lib/python3.9/threading.py", line 910, in run
    self._target(*self._args, **self._kwargs)
  File "/usr/local/lib/python3.9/concurrent/futures/thread.py", line 77, in _worker
    work_item.run()
  File "/usr/local/lib/python3.9/concurrent/futures/thread.py", line 52, in run
    result = self.fn(*self.args, **self.kwargs)
  File "/usr/src/homeassistant/homeassistant/components/recorder/__init__.py", line 542, in shutdown
    self.join()
  File "/usr/local/lib/python3.9/threading.py", line 1053, in join
    self._wait_for_tstate_lock()
  File "/usr/local/lib/python3.9/threading.py", line 1069, in _wait_for_tstate_lock
    elif lock.acquire(block, timeout):
